Workbook

Sheet Sheet1
A1: Code | B1: Sub-category | C1: Սեռ(կանացի,տղամարդ,աղջիկ,տղա) | D1: Բրուտտո քաշ | E1: Նետտո քաշ | G1: Քանակ հատ | H1: Բրենդ | I1: Ծագման երկիր | J1: Ապրանքի մատերիալ
A2: 40000001111 | B2: հուդի | C2: տղամարդու | D2: 55 | E2: 55 | F2: =E2/1000 -> 0.055 | G2: 1 | H2: PETROL | I2: Bangladesh | J2: բամբակ/պոլիեսթեր
A3: 40000001112 | B3: բլուզ | C3: տղամարդու | D3: 334 | E3: 334 | F3: =E3/1000 -> 0.334 | G3: 1 | H3: PETROL | I3: Bangladesh | J3: ակրիլ/բամբակ
A4: 40000001113 | B4: 35-ից բաձր կոշիկ | C4: տղամարդու | D4: 1086 | E4: 1086 | F4: =E4/1000 -> 1.086 | G4: 1 | H4: REGATTA | I4: China | J4: տակը ռետին, վրան կտոր
A5: 40000001114 | B5: 35-ից բաձր կոշիկ | C5: կին | D5: 42 | E5: 42 | F5: =E5/1000 -> 0.042 | G5: 1 | H5: REEBOK | I5: China | J5: տակը ռետին, վրան կտոր
A6: 40000001110 | B6: տաբատ | C6: տղայի | D6: 304 | E6: 304 | F6: =E6/1000 -> 0.304 | G6: 1 | H6: S.OLIVER | I6: Bangladesh | J6: բամբակ
A7: 40000001109 | B7: 35-ից բաձր կոշիկ | C7: կին | D7: 850 | E7: 1418 | F7: =E7/1000 -> 1.418 | G7: 1 | H7: RAGE AGE | I7: Poland | J7: տակը պոլիմեր, վրան զամշ
A8: 40000001108 | B8: 35-ից բարձր հողաթափ | C8: յունիսեքս | D8: 388 | E8: 582 | F8: =E8/1000 -> 0.582 | G8: 1 | H8: UGG | I8: Vietnam | J8: բուրդ/լիոցել
A9: 40000001107 | B9: վերարկու | C9: կին | D9: 1102 | E9: 1102 | F9: =E9/1000 -> 1.102 | G9: 1 | H9: TOMTAILOR | I9: Vietnam | J9: պոլիեսթեր
A10: 40000001106 | B10: բլուզ | C10: տղամարդու | D10: 344 | E10: 344 | F10: =E10/1000 -> 0.344 | G10: 1 | H10: PETROL | I10: Bangladesh | J10: բամբակ/ակրիլ
A11: 40000001105 | B11: վերարկու | C11: տղամարդու | D11: 1136 | E11: 1136 | F11: =E11/1000 -> 1.136 | G11: 1 | H11: PETROL | I11: China | J11: պոլիեսթեր
A12: 40000001104 | B12: վերարկու | C12: տղամարդու | D12: 1194 | E12: 1194 | F12: =E12/1000 -> 1.194 | G12: 1 | H12: PETROL | I12: China | J12: պոլիեսթեր
A13: 40000001103 | B13: վերարկու | C13: տղամարդու | D13: 1076 | E13: 1076 | F13: =E13/1000 -> 1.076 | G13: 1 | H13: PETROL | I13: China | J13: պոլիեսթեր
... A841: 40000000277 | B841: բլուզ | C841: կին | D841: 160 | E841: 160 | F841: =E841/1000 -> 0.16 | G841: 1 | H841: DE FACTO | I841: Turkey | J841: պոլիեսթեր
A842: 40000000276 | B842: սեթ 3 շապիկ + տաբատ + գլխարկ | C842: կին | D842: 404 | E842: 404 | F842: =E842/1000 -> 0.404 | G842: 3 set | H842: DE FACTO | I842: Turkey | J842: պոլիեսթեր
A843: 40000000275 | B843: վերնաշապիկ | C843: կին | D843: 248 | E843: 248 | F843: =E843/1000 -> 0.248 | G843: 1 | H843: DE FACTO | I843: Bangladesh | J843: բամբակ
A844: 40000000274 | B844: մինչև 1 կոմբինեզոն | C844: տղայի | D844: 98 | E844: 98 | F844: =E844/1000 -> 0.098 | G844: 1 | H844: DE FACTO | I844: Turkey | J844: բամբակ
A845: 40000000273 | B845: Տաբատ | C845: կին | D845: 354 | E845: 354 | F845: =E845/1000 -> 0.354 | G845: 1 | H845: DE FACTO | I845: Turkey | J845: վիսկոզ/բամբակ
A846: 40000000272 | B846: բլուզ | C846: կին | D846: 86 | E846: 86 | F846: =E846/1000 -> 0.086 | G846: 1 | H846: DE FACTO | I846: Turkey | J846: պոլիեսթեր
A847: 40000000271 | B847: բլուզ | C847: կին | D847: 260 | E847: 260 | F847: =E847/1000 -> 0.26 | G847: 1 | H847: DE FACTO | I847: Turkey | J847: բամբակ
A848: 40000000270 | B848: շապիկ | C848: տղամարդու | D848: 178 | E848: 178 | F848: =E848/1000 -> 0.178 | G848: 1 | H848: DE FACTO | I848: Turkey | J848: բամբակ
A849: 40000000269 | B849: ջինսե տաբատ | C849: կին | D849: 510 | E849: 510 | F849: =E849/1000 -> 0.51 | G849: 1 | H849: DE FACTO | I849: Bangladesh | J849: բամբակ
A850: 40000000268 | B850: շապիկ | C850: տղամարդու | D850: 126 | E850: 126 | F850: =E850/1000 -> 0.126 | G850: 1 | H850: DE FACTO | I850: Turkey | J850: բամբակ
A851: 40000000267 | B851: ջինսե տաբատ | C851: կին | D851: 676 | E851: 676 | F851: =E851/1000 -> 0.676 | G851: 1 | H851: DE FACTO | I851: Turkey | J851: բամբակ
A852: 40000000266 | B852: սվիտեր | C852: կին | D852: 266 | E852: 266 | F852: =E852/1000 -> 0.266 | G852: 1 | H852: DE FACTO | I852: Turkey | J852: պոլիեսթեր
A853: 40000000265 | B853: բլուզ | C853: կին | D853: 142 | E853: 142 | F853: =E853/1000 -> 0.142 | G853: 1 | H853: DE FACTO | I853: Bangladesh | J853: բամբակ
A854: 40000000264 | B854: ջինսե տաբատ | C854: կին | D854: 544 | E854: 544 | F854: =E854/1000 -> 0.544 | G854: 1 | H854: DE FACTO | I854: Bangladesh | J854: բամբակ
... A948: 60000000469 | B948: լողազգեստ | C948: կին | D948: 214 | E948: 214 | F948: =E948/1000 -> 0.214 | G948: 1 | H948: ASOS | I948: Albania | J948: պոլիեսթեր
A949: 60000000468 | B949: տոպ | C949: կին | D949: 0.056 | E949: 0.056 | F949: =E949 -> 0.056 | G949: 1 | H949: COLLUSION | I949: Bangladesh | J949: բամբակ
A950: 60000000467 | B950: տոպ | C950: կին | D950: 0.056 | E950: 0.056 | F950: =E950 -> 0.056 | G950: 1 | H950: COLLUSION | I950: Bangladesh | J950: բամբակ
A951: 60000000466 | B951: տոպ | C951: կին | D951: 0.056 | E951: 0.056 | F951: =E951 -> 0.056 | G951: 1 | H951: COLLUSION | I951: Bangladesh | J951: բամբակ
A952: 60000000465 | B952: տոպ | C952: կին | D952: 0.04 | E952: 0.04 | F952: =E952 -> 0.04 | G952: 1 | H952: COLLUSION | I952: Bangladesh | J952: բամբակ
A953: 60000000464 | B953: տոպ | C953: կին | D953: 0.04 | E953: 0.04 | F953: =E953 -> 0.04 | G953: 1 | H953: COLLUSION | I953: Bangladesh | J953: բամբակ
A954: 60000000463 | B954: տոպ | C954: կին | D954: 0.04 | E954: 0.04 | F954: =E954 -> 0.04 | G954: 1 | H954: COLLUSION | I954: Bangladesh | J954: բամբակ
A955: 60000000462 | B955: տոպ | C955: կին | D955: 0.04 | E955: 0.04 | F955: =E955 -> 0.04 | G955: 1 | H955: COLLUSION | I955: Bangladesh | J955: բամբակ
A956: 60000000461 | B956: տոպ | C956: կին | D956: 0.04 | E956: 0.04 | F956: =E956 -> 0.04 | G956: 1 | H956: COLLUSION | I956: Bangladesh | J956: բամբակ
A957: 60000000460 | B957: կիսաշրջազգեստ | C957: կին | D957: 226 | E957: 226 | F957: =E957/1000 -> 0.226 | G957: 1 | H957: ASOS | I957: India | J957: բամբակ
A958: 60000000459 | B958: կիսաշրջազգեստ | C958: կին | D958: 226 | E958: 226 | F958: =E958/1000 -> 0.226 | G958: 1 | H958: ASOS | I958: India | J958: բամբակ
A959: 60000000458 | B959: շապիկ | C959: տղամարդու | D959: 118 | E959: 118 | F959: =E959/1000 -> 0.118 | G959: 1 | H959: VANS | I959: Georgia | J959: բամբակ
A960: 60000000457 | B960: Տաբատ | C960: կին | D960: 184 | E960: 184 | F960: =E960/1000 -> 0.184 | G960: 1 | H960: ASOS | I960: Bangladesh | J960: բամբակ
...

Sheet Sheet2
B1: N | C1: Code | D1: HS code | E1: name | F1: Sub-category | G1: Սեռ(կանացի,տղամարդ,աղջիկ,տղա) | H1: Բրուտտո քաշ | I1: Նետտո քաշ | J1: Net kg | K1: Քանակ հատ | L1: Բրենդ | M1: Ծագման երկիր | N1: Ապրանքի մատերիալ
B2: 1 | C2: 40000001111 | D2: 61102091000 | E2: ՏՂԱՄԱՐԴՈՒ ՀՈՒԴԻՆԵՐ ԲԱՄԲԱԿԵ ՄԱՆՎԱԾՔԻՑ | F2: հուդի | G2: տղամարդու | H2: 55 | I2: 55 | J2: =I2/1000 -> 0.055 | K2: 1 | L2: PETROL | M2: Bangladesh | N2: բամբակ/պոլիեսթեր | O2: =VLOOKUP(C2,#REF!,#REF!) -> #REF!
B3: 2 | C3: 40000001112 | D3: 61103091000 | E3: ՏՂԱՄԱՐԴՈՒ ՍՎԻՏՐԵՐ ՔԻՄԻԱԿԱՆ ԹԵԼԵՐԻՑ | F3: սվիտեր | G3: տղամարդու | H3: 334 | I3: 334 | J3: =I3/1000 -> 0.334 | K3: 1 | L3: PETROL | M3: Bangladesh | N3: ակրիլ/բամբակ | O3: =VLOOKUP(C:C,#REF!,#REF!) -> #REF!
B4: 3 | C4: 40000001113 | D4: 64041990000 | E4: ՏՂԱՄԱՐԴՈՒ ԿՈՇԻԿ ՏԵՔՍԻԼԵ ԵՐԵՍԱՄԱՍՈՎ ՌԵՏԻՆԵ ԿՈՇԿԱՏԱԿՈՎ | F4: 35-ից բաձր կոշիկ | G4: տղամարդու | H4: 1086 | I4: 1086 | J4: =I4/1000 -> 1.086 | K4: 1 | L4: REGATTA | M4: China | N4: տակը ռետին, վրան կտոր | O4: =VLOOKUP(C:C,#REF!,#REF!) -> #REF!
B5: 4 | C5: 40000001114 | D5: 64041990000 | E5: ԿԱՆԱՑԻ ԿՈՇԻԿ ՏԵՔՍԻԼԵ ԵՐԵՍԱՄԱՍՈՎ ՌԵՏԻՆԵ ԿՈՇԿԱՏԱԿՈՎ | F5: 35-ից բաձր կոշիկ | G5: կին | H5: 42 | I5: 42 | J5: =I5/1000 -> 0.042 | K5: 1 | L5: REEBOK | M5: China | N5: տակը ռետին, վրան կտոր
B6: 5 | C6: 40000001110 | D6: 62034235000 | E6: ՏՂԱՅԻ ՏԱԲԱՏՆԵՐ ԲԱՄԲԱԿԵ ՄԱՆՎԱԾՔԻՑ | F6: տաբատ | G6: տղայի | H6: 304 | I6: 304 | J6: =I6/1000 -> 0.304 | K6: 1 | L6: S.OLIVER | M6: Bangladesh | N6: բամբակ
B7: 6 | C7: 40000001109 | D7: 64039998000 | E7: ԿԱՆԱՑԻ ԿՈՇԻԿ ԲՆԱԿԱՆ ԿԱՇՎԵ ԵՐԵՍԱՄԱՍՈՎ , ՊՈԼԻՄԵՐԱՅԻՆ ԿՈՇԿԱՏԱԿՈՎ | F7: 35-ից բաձր կոշիկ | G7: կին | H7: 1418 | I7: 850 | J7: =I7/1000 -> 0.85 | K7: 1 | L7: RAGE AGE | M7: Poland | N7: տակը պոլիմեր, վրան զամշ
B8: 7 | C8: 40000001108 | D8: 64041910000 | E8: ՏՂԱՄԱՐԴՈՒ ՀՈՂԱԹԱՓ ՏԵՔՍՏԻԼԵ ԵՐԵՍԱՄԱՍՈՎ , ՊՈԼԻՄԵՐԱՅԻՆ ԿՈՇԿԱՏՈՎ | F8: 35-ից բարձր հողաթափ | G8: յունիսեքս | H8: 582 | I8: 388 | J8: =I8/1000 -> 0.388 | K8: 1 | L8: UGG | M8: Vietnam | N8: բուրդ/լիոցել
B9: 8 | C9: 40000001107 | D9: 62024000010 | E9: ԿԱՆԱՑԻ ՎԵՐԱՐԿՈՒ ՔԻՄԻԱԿԱՆ ԹԵԼԵՐԻՑ | F9: վերարկու | G9: կին | H9: 1102 | I9: 1102 | J9: =I9/1000 -> 1.102 | K9: 1 | L9: TOMTAILOR | M9: Vietnam | N9: պոլիեսթեր
B10: 9 | C10: 40000001106 | D10: 61102091000 | E10: ՏՂԱՄԱՐԴՈՒ ՍՎԻՏՐԵՐ ԲԱՄԲԱԿԵ ՄԱՆՎԱԾՔԻՑ | F10: սվիտեր | G10: տղամարդու | H10: 344 | I10: 344 | J10: =I10/1000 -> 0.344 | K10: 1 | L10: PETROL | M10: Bangladesh | N10: բամբակ/ակրիլ
B11: 10 | C11: 40000001105 | D11: 62014000000 | E11: ՏՂԱՄԱՐԴՈՒ ՎԵՐԱՐԿՈՒ ՔԻՄԻԱԿԱՆ ԹԵԼԵՐԻՑ | F11: վերարկու | G11: տղամարդու | H11: 1136 | I11: 1136 | J11: =I11/1000 -> 1.136 | K11: 1 | L11: PETROL | M11: China | N11: պոլիեսթեր
B12: 11 | C12: 40000001104 | D12: 62014000000 | E12: ՏՂԱՄԱՐԴՈՒ ՎԵՐԱՐԿՈՒ ՔԻՄԻԱԿԱՆ ԹԵԼԵՐԻՑ | F12: վերարկու | G12: տղամարդու | H12: 1194 | I12: 1194 | J12: =I12/1000 -> 1.194 | K12: 1 | L12: PETROL | M12: China | N12: պոլիեսթեր
B13: 12 | C13: 40000001103 | D13: 62014000000 | E13: ՏՂԱՄԱՐԴՈՒ ՎԵՐԱՐԿՈՒ ՔԻՄԻԱԿԱՆ ԹԵԼԵՐԻՑ | F13: վերարկու | G13: տղամարդու | H13: 1076 | I13: 1076 | J13: =I13/1000 -> 1.076 | K13: 1 | L13: PETROL | M13: China | N13: պոլիեսթեր
B14: 13 | C14: 40000001102 | D14: 62014000000 | E14: ՏՂԱՄԱՐԴՈՒ ՎԵՐԱՐԿՈՒ ՔԻՄԻԱԿԱՆ ԹԵԼԵՐԻՑ | F14: վերարկու | G14: տղամարդու | H14: 1038 | I14: 1038 | J14: =I14/1000 -> 1.038 | K14: 1 | L14: PETROL | M14: China | N14: պոլիեսթեր
B15: 14 | C15: 40000001101 | D15: 62024000010 | E15: ԿԱՆԱՑԻ ՎԵՐԱՐԿՈՒ ՔԻՄԻԱԿԱՆ ԹԵԼԵՐԻՑ | F15: վերարկու | G15: կին | H15: 1060 | I15: 1060 | J15: =I15/1000 -> 1.06 | K15: 1 | L15: TOMTAILOR | M15: Vietnam | N15: պոլիեսթեր
B16: 15 | C16: 40000001100 | D16: 61102091000 | E16: ՏՂԱՄԱՐԴՈՒ ՀՈՒԴԻՆԵՐ ԲԱՄԲԱԿԵ ՄԱՆՎԱԾՔԻՑ | F16: հուդի | G16: տղամարդու | H16: 926 | I16: 926 | J16: =I16/1000 -> 0.926 | K16: 1 | L16: CARHARTT | M16: Pakistan | N16: բամբակ/պոլիեսթեր
... B211: 210 | C211: 40000000905 | D211: 64039991000 | E211: ԱՂՋԿԱ ԲՈԿՈՏԻԿՆԵՐ ԲՆԱԿԱՆ ԿԱՇՎԵ ԵՐԵՍԱՄԱՍՈՎ , ՌԵՏԻՆԵ ԿՈՇԿԱՏԱԿՈՎ ՄԻՆՉԵՎ 24ՍՄ ՆԵՐԲԱՆԻ ԵՐԿԱՐՈՒԹՅԱՄԲ | F211: սանդալ մինչև 35 | G211: մանկական | H211: 256 | I211: 160 | J211: =I211/1000 -> 0.16 | K211: 1 | L211: CHICCO | M211: China | N211: տակը ռետին, վրան կաշի
B212: 211 | C212: 40000000904 | D212: 90041091000 | E212: ԱՐԵՎԱՊԱՇՏՊԱՆ ԱԿՆՈՑՆԵՐ ՏԵՍՈՂՈՒԹՅՈՒՆԸ ՉՇՏԿՈՂ ՈՉ ԹԱՆԿԱՐԺԵՔ ՄԵՏԱՂՆԵՐԻՑ, ՊԼԱՍՍՏՄԱՍՍԱՅԻՑ ՈՍՊՆՅԱԿՆԵՐՈՎ | F212: ակնոց | G212: կին | H212: 86 | I212: 86 | J212: =I212/1000 -> 0.086 | K212: 1 | L212: MONCLER | M212: Italy | N212: պլաստմաս
B213: 212 | C213: 40000000903 | D213: 61091000000 | E213: ԿԱՆԱՑԻ ՇԱՊԻԿՆԵՐ ԲԱՄԲԱԿԵ ՄԱՆՎԱԾՔԻՑ | F213: շապիկ | G213: կին | H213: 120 | I213: 120 | J213: =I213/1000 -> 0.12 | K213: 1 | L213: CAVALLI CLASS | M213: Bangladesh | N213: բամբակ
B214: 213 | C214: 40000000902 | D214: 61112090000 | E214: ՏՂԱ ԵՐԵԽԱՅԻ ԲՈԴԻ ԲԱՄԲԱԿԵ ՄԱՆՎԱԾՔԻՑ ՄԻՆՉԵՎ 86 ՍՄ ՀԱՍԱԿ ՈՒՆԵՑՈՂ 1 ՀԱՎԱՔԱԾՈՒ 2 ՀԱՏԻՑ | F214: բոդի մինչև 1 սեթ 2 | G214: մանկական | H214: 68 | I214: 68 | J214: =I214/1000 -> 0.068 | K214: 1 | L214: CHICCO | M214: India | N214: բամբակ
B215: 214 | C215: 40000000901 | D215: 61091000000 | E215: ԿԱՆԱՑԻ ՇԱՊԻԿՆԵՐ ԲԱՄԲԱԿԵ ՄԱՆՎԱԾՔԻՑ | F215: շապիկ | G215: կին | H215: 110 | I215: 110 | J215: =I215/1000 -> 0.11 | K215: 1 | L215: CAVALLI CLASS | M215: Bangladesh | N215: բամբակ
B216: 215 | C216: 40000000900 | D216: 64039991000 | E216: ՏՂԱՅԻ ՍՊՈՐՏԱՅԻՆ ՈՃԻ ԿՈՇԻԿ ԲՆԱԿԱՆ ԿԱՇՎԵ ԵՐԵՍԱՄԱՍՈՎ , ՌԵՏԻՆԵ ԿՈՇԿԱՏԱԿՈՎ ՄԻՆՉԵՎ 24ՍՄ ՆԵՐԲԱՆԻ ԵՐԿԱՐՈՒԹՅԱՄԲ | F216: կեդ մինչև 35 | G216: տղայի | H216: 278 | I216: 184 | J216: =I216/1000 -> 0.184 | K216: 1 | L216: CHICCO | M216: China | N216: տակը ռետին, վրան կաշի
B217: 216 | C217: 40000000899 | D217: 64039991000 | E217: ԱՂՋԿԱ ԿՈՇԻԿ ԲՆԱԿԱՆ ԿԱՇՎԵ ԵՐԵՍԱՄԱՍՈՎ , ՊՈԼԻՄԵՐԱՅԻՆ ԿՈՇԿԱՏԱԿՈՎ ՄԻՆՉԵՎ 24ՍՄ ՆԵՐԲԱՆԻ ԵՐԿԱՐՈՒԹՅԱՄԲ | F217: կոշիկ մինչև 35 | G217: աղջկա | H217: 30 | I217: 30 | J217: =I217/1000 -> 0.03 | K217: 1 | L217: CHICCO | M217: China | N217: տակը տեքստիլ, վրան կաշի
B218: 217 | C218: 40000000898 | D218: 64052099000 | E218: ՏՂԱՅԻ ԲՈԿՈՏԻԿ ՏԵՔՍԻԼԵ | F218: սանդալ մինչև 35 | G218: մանկական | H218: 36 | I218: 36 | J218: =I218/1000 -> 0.036 | K218: 1 | L218: CHICCO | M218: China | N218: կտոր
B219: 218 | C219: 40000000897 | D219: 64041990000 | E219: ԱՂՋԿԱ ԲՈԿՈՏԻԿՆԵՐ ՏԵՔՍԻԼԵ ԵՐԵՍԱՄԱՍՈՎ ՌԵՏԻՆԵ ԿՈՇԿԱՏԱԿՈՎ | F219: սանդալ մինչև 35 | G219: մանկական | H219: 332 | I219: 332 | J219: =I219/1000 -> 0.332 | K219: 1 | L219: CHICCO | M219: China | N219: տակը ռետին, վրան կտոր
B220: 219 | C220: 40000000896 | D220: 64041990000 | E220: ԱՂՋԿԱ ԲՈԿՈՏԻԿՆԵՐ ՏԵՔՍԻԼԵ ԵՐԵՍԱՄԱՍՈՎ ՌԵՏԻՆԵ ԿՈՇԿԱՏԱԿՈՎ | F220: սանդալ մինչև 35 | G220: մանկական | H220: 332 | I220: 332 | J220: =I220/1000 -> 0.332 | K220: 1 | L220: CHICCO | M220: China | N220: տակը ռետին, վրան կտոր
B221: 220 | C221: 40000000895 | D221: 64039116000 | E221: ՏՂԱՄԱՐԴՈՒ ԿԻՍԱՃՏՔԱՎՈՐ ԿՈՇԻԿՆԵՐ ԲՆԱԿԱՆ ԿԱՇՎԵ ԵՐԵՍԱՄԱՍՈՎ ՌԵՏԻՆԵ ԿՈՇԿԱՏԱԿՈՎ | F221: 35-ից բարձր կիսաճտքավոր կոշիկ | G221: տղամարդու | H221: 1650 | I221: 1340 | J221: =I221/1000 -> 1.34 | K221: 1 | L221: SALEVA | M221: Vietnam | N221: տակը ռետին, վրան կաշի
B222: 221 | C222: 40000000894 | D222: 64029998000 | E222: ԿԱՆԱՑԻ ՍՊՈՐՏԱՅԻՆ ՈՃԻ ԿՈՇԻԿ ԱՐՀԵՍՏԱԿԱՆ ԿԱՇՎԵ ԵՐԵՍԱՄԱՍՈՎ , ՊՈԼԻՄԵՐԱՅԻՆ ԿՈՇԿԱՏԱԿՈՎ | F222: կեդ 35-ից բարձր | G222: կին | H222: 684 | I222: 550 | J222: =I222/1000 -> 0.55 | K222: 1 | L222: KAPPA | M222: China | N222: տակը պոլիմեր, վրան արհեստական կաշի
B223: 222 | C223: 40000000893 | D223: 90041091000 | E223: ԱՐԵՎԱՊԱՇՏՊԱՆ ԱԿՆՈՑՆԵՐ ՏԵՍՈՂՈՒԹՅՈՒՆԸ ՉՇՏԿՈՂ ՈՉ ԹԱՆԿԱՐԺԵՔ ՄԵՏԱՂՆԵՐԻՑ, ՊԼԱՍՍՏՄԱՍՍԱՅԻՑ ՈՍՊՆՅԱԿՆԵՐՈՎ | F223: ակնոց | G223: կին | H223: 366 | I223: 366 | J223: =I223/1000 -> 0.366 | K223: 1 | L223: VIVIENNE WESTWOOD | M223: UK | N223: պլաստմաս
B224: 223 | C224: 40000000892 | D224: 90041091000 | E224: ԱՐԵՎԱՊԱՇՏՊԱՆ ԱԿՆՈՑՆԵՐ ՏԵՍՈՂՈՒԹՅՈՒՆԸ ՉՇՏԿՈՂ ՈՉ ԹԱՆԿԱՐԺԵՔ ՄԵՏԱՂՆԵՐԻՑ, ՊԼԱՍՍՏՄԱՍՍԱՅԻՑ ՈՍՊՆՅԱԿՆԵՐՈՎ | F224: ակնոց | G224: կին | H224: 350 | I224: 350 | J224: =I224/1000 -> 0.35 | K224: 1 | L224: VIVIENNE WESTWOOD | M224: UK | N224: պլաստմաս
B225: 224 | C225: 40000000891 | D225: 62023000000 | E225: ԿԱՆԱՑԻ ԲԱՃԿՈՆՆԵՐ ԲԱՄԲԱԿԵ ՄԱՆՎԱԾՔԻՑ | F225: բաճկոն | G225: կին | H225: 1238 | I225: 1238 | J225: =I225/1000 -> 1.238 | K225: 1 | L225: LIU.JO | M225: China | N225: բամբակ
B226: 225 | C226: 40000000890 | D226: 62014000000 | E226: ՏՂԱՄԱՐԴՈՒ ԲԱՃԿՈՆՆԵՐ ՔԻՄԻԱԿԱՆ ԹԵԼԵՐԻՑ | F226: բաճկոն | G226: տղամարդու | H226: 884 | I226: 884 | J226: =I226/1000 -> 0.884 | K226: 1 | L226: LIU.JO | M226: China | N226: պոլիեսթեր
B227: 226 | C227: 40000000889 | D227: 62014000000 | E227: ՏՂԱՄԱՐԴՈՒ ԲԱՃԿՈՆՆԵՐ ՔԻՄԻԱԿԱՆ ԹԵԼԵՐԻՑ | F227: բաճկոն | G227: տղամարդու | H227: 960 | I227: 960 | J227: =I227/1000 -> 0.96 | K227: 1 | L227: LIU.JO | M227: China | N227: պոլիեսթեր
B228: 227 | C228: 40000000888 | D228: 62014000000 | E228: ՏՂԱՄԱՐԴՈՒ ԲԱՃԿՈՆՆԵՐ ՔԻՄԻԱԿԱՆ ԹԵԼԵՐԻՑ | F228: բաճկոն | G228: տղամարդու | H228: 1044 | I228: 1044 | J228: =I228/1000 -> 1.044 | K228: 1 | L228: LIU.JO | M228: China | N228: պոլիեսթեր
B229: 228 | C229: 40000000887 | D229: 62014000000 | E229: ՏՂԱՄԱՐԴՈՒ ԲԱՃԿՈՆՆԵՐ ՔԻՄԻԱԿԱՆ ԹԵԼԵՐԻՑ | F229: բաճկոն | G229: տղամարդու | H229: 1010 | I229: 1010 | J229: =I229/1000 -> 1.01 | K229: 1 | L229: LIU.JO | M229: China | N229: պոլիեսթեր
B230: 229 | C230: 40000000886 | D230: 62014000000 | E230: ՏՂԱՄԱՐԴՈՒ ԲԱՃԿՈՆՆԵՐ ՔԻՄԻԱԿԱՆ ԹԵԼԵՐԻՑ | F230: բաճկոն | G230: տղամարդու | H230: 1088 | I230: 1088 | J230: =I230/1000 -> 1.088 | K230: 1 | L230: LIU.JO | M230: China | N230: պոլիեսթեր
B231: 230 | C231: 40000000885 | D231: 62014000000 | E231: ՏՂԱՄԱՐԴՈՒ ԲԱՃԿՈՆՆԵՐ ՔԻՄԻԱԿԱՆ ԹԵԼԵՐԻՑ | F231: բաճկոն | G231: տղամարդու | H231: 748 | I231: 748 | J231: =I231/1000 -> 0.748 | K231: 1 | L231: LIU.JO | M231: China | N231: պոլիեսթեր
B232: 231 | C232: 40000000884 | D232: 62014000000 | E232: ՏՂԱՄԱՐԴՈՒ ԲԱՃԿՈՆՆԵՐ ՔԻՄԻԱԿԱՆ ԹԵԼԵՐԻՑ | F232: բաճկոն | G232: տղամարդու | H232: 752 | I232: 752 | J232: =I232/1000 -> 0.752 | K232: 1 | L232: LIU.JO | M232: China | N232: պոլիեսթեր
B233: 232 | C233: 40000000883 | D233: 62014000000 | E233: ՏՂԱՄԱՐԴՈՒ ԲԱՃԿՈՆՆԵՐ ՔԻՄԻԱԿԱՆ ԹԵԼԵՐԻՑ | F233: բաճկոն | G233: տղամարդու | H233: 706 | I233: 706 | J233: =I233/1000 -> 0.706 | K233: 1 | L233: LIU.JO | M233: China | N233: պոլիեսթեր
B234: 233 | C234: 40000000882 | D234: 62023000000 | E234: ԿԱՆԱՑԻ ԲԱՃԿՈՆՆԵՐ ԲԱՄԲԱԿԵ ՄԱՆՎԱԾՔԻՑ | F234: բաճկոն | G234: կին | H234: 1148 | I234: 1148 | J234: =I234/1000 -> 1.148 | K234: 1 | L234: LIU.JO | M234: China | N234: բամբակ
...

Sheet RE (2)
A1: N | B1: Code | C1: HS code | D1: name | E1: Sub-category | F1: Sub-category | G1: Sub-category id | H1: Gender | I1: Gender id | J1: Netto | K1: Brutto | L1: pc | M1: Brand | N1: Brand id | O1: Country | P1: Country id | Q1: Country | R1: Material | S1: Material | T1: Material id | U1: Package | V1: Package Id | W1: Size | X1: Size id | Y1: Original price | Z1: Color | AA1: Color id
A2: 1 | B2: 60000001980 | C2: 62046239000 | D2: ԿԱՆԱՑԻ ԵՎ ԱՂՋԿԱ ՏԱԲԱՏՆԵՐ ԲԱՄԲԱԿԵ ՄԱՆՎԱԾՔԻՑ | E2: =PROPER(F2) -> Տաբատներ | F2: տաբատներ | G2: =VLOOKUP(E2,subcategory!A:B,2,0) -> 93 | H2: աղջկա | I2: =VLOOKUP(H2,gender!A:B,2,0) -> #N/A | J2: 125 | K2: 125 | L2: 1 | M2: CHICCO | N2: =VLOOKUP(M2,brand!A:B,2,0) -> 608 | O2: =UPPER(Q2) -> BANGLADESH | P2: =VLOOKUP(O2,country!A:B,2,0) -> 7485 | Q2: BANGLADESH | R2: =PROPER(S2) -> Բամբակ | S2: բամբակ | T2: =VLOOKUP(R2,material!A:B,2,0) -> 9 | U2: chicco | W2: 6տ. | X2: =VLOOKUP(W2,SIZE!A:B,2,0) -> #N/A | Y2: 10,99 | Z2: կապույտ | AA2: =VLOOKUP(Z2,COLOR!A:B,2,0) -> 5
A3: 2 | B3: 60000001978 | C3: 61046200000 | D3: ԱՂՋԿԱ ՇՈՐՏԵՐ ԲԱՄԲԱԿԵ ՄԱՆՎԱԾՔԻՑ | E3: =PROPER(F3) -> Շորտ | F3: շորտ | G3: =VLOOKUP(E3,subcategory!A:B,2,0) -> 24 | H3: աղջկա | I3: =VLOOKUP(H3,gender!A:B,2,0) -> #N/A | J3: 55 | K3: 55 | L3: 1 | M3: CHICCO | N3: =VLOOKUP(M3,brand!A:B,2,0) -> 608 | O3: =UPPER(Q3) -> BANGLADESH | P3: =VLOOKUP(O3,country!A:B,2,0) -> 7485 | Q3: BANGLADESH | R3: =PROPER(S3) -> Բամբակ | S3: բամբակ | T3: =VLOOKUP(R3,material!A:B,2,0) -> 9 | U3: chicco | W3: 4տ. | X3: =VLOOKUP(W3,SIZE!A:B,2,0) -> #N/A | Y3: 9,99 | Z3: սև | AA3: =VLOOKUP(Z3,COLOR!A:B,2,0) -> 20
A4: 3 | B4: 40000001949 | C4: 64041990000 | D4: ՏՂԱՅԻ ԿԻՍԱՃՏՔԱՎՈՐ ԿՈՇԻԿՆԵՐ ՏԵՔՏՍԻԼԵ ԵՐԵՍԱՄԱՍՈՎ ՌԵՏԻՆԵ ԿՈՇԿԱՏԱԿՈՎ | E4: =PROPER(F4) -> Սպորտ Կիսաճտքավոր | F4: սպորտ կիսաճտքավոր | G4: =VLOOKUP(E4,subcategory!A:B,2,0) -> #N/A | H4: տղա | I4: =VLOOKUP(H4,gender!A:B,2,0) -> #N/A | J4: 735 | K4: 735 | L4: 1 | M4: LD | N4: =VLOOKUP(M4,brand!A:B,2,0) -> #N/A | O4: =UPPER(Q4) -> GERMANY | P4: =VLOOKUP(O4,country!A:B,2,0) -> 1725 | Q4: GERMANY | R4: =PROPER(S4) -> Ռեզին, Պոլիեսթեր | S4: ռեզին, պոլիեսթեր | T4: =VLOOKUP(R4,material!A:B,2,0) -> #N/A | U4: ALDY | W4: 35 | X4: =VLOOKUP(W4,SIZE!A:B,2,0) -> 217 | Y4: 0 | Z4: կապույտ | AA4: =VLOOKUP(Z4,COLOR!A:B,2,0) -> 5
A5: 4 | B5: 40000001947 | C5: 64041990000 | D5: ՏՂԱՅԻ ԿԻՍԱՃՏՔԱՎՈՐ ԿՈՇԻԿՆԵՐ ՏԵՔՏՍԻԼԵ ԵՐԵՍԱՄԱՍՈՎ ՌԵՏԻՆԵ ԿՈՇԿԱՏԱԿՈՎ | E5: =PROPER(F5) -> Սպորտ Կիսաճտքավոր | F5: սպորտ կիսաճտքավոր | G5: =VLOOKUP(E5,subcategory!A:B,2,0) -> #N/A | H5: տղա | I5: =VLOOKUP(H5,gender!A:B,2,0) -> #N/A | J5: 460 | K5: 460 | L5: 1 | M5: LILY & DAN | N5: =VLOOKUP(M5,brand!A:B,2,0) -> #N/A | O5: =UPPER(Q5) -> GERMANY | P5: =VLOOKUP(O5,country!A:B,2,0) -> 1725 | Q5: GERMANY | R5: =PROPER(S5) -> Ռեզին, Պոլիեսթեր | S5: ռեզին, պոլիեսթեր | T5: =VLOOKUP(R5,material!A:B,2,0) -> #N/A | U5: ALDY | W5: 26 | X5: =VLOOKUP(W5,SIZE!A:B,2,0) -> 484 | Y5: 0 | Z5: կապույտ | AA5: =VLOOKUP(Z5,COLOR!A:B,2,0) -> 5
A6: 5 | B6: 60000004127 | C6: 61103099000 | D6: ԿԱՆԱՑԻ ՍՎԻՏՐԵՐ ՔԻՄԱԿԱՆ ԹԵԼԵՐԻՑ | E6: =PROPER(F6) -> Սվիտրեր | F6: Սվիտրեր | G6: =VLOOKUP(E6,subcategory!A:B,2,0) -> 88 | H6: կին | I6: =VLOOKUP(H6,gender!A:B,2,0) -> #N/A | J6: 434 | K6: 434 | L6: 1 | M6: DEFACTO | N6: =VLOOKUP(M6,brand!A:B,2,0) -> 823 | O6: =UPPER(Q6) -> TURKEY | P6: =VLOOKUP(O6,country!A:B,2,0) -> 1840 | Q6: TURKEY | R6: =PROPER(S6) -> 72% Ակրիլ, 24% Պոլիեսթեր, 4% Վիսկոզ | S6: 72% ակրիլ, 24% պոլիեսթեր, 4% վիսկոզ | T6: =VLOOKUP(R6,material!A:B,2,0) -> #N/A | U6: DEFACTO | W6: XL | X6: =VLOOKUP(W6,SIZE!A:B,2,0) -> 124 | Y6: 0 | Z6: բեժ | AA6: =VLOOKUP(Z6,COLOR!A:B,2,0) -> #N/A
A7: 6 | B7: 60000004105 | C7: 61044300000 | D7: ԿԱՆԱՑԻ ԵՎ ԱՂՋԿԱ ՇՐՋԱԶԳԵՍՏՆԵՐ ՍԻՆԹԵՏԻԿ ԹԵԼԵՐԻՑ | E7: =PROPER(F7) -> Զգեստ | F7: զգեստ | G7: =VLOOKUP(E7,subcategory!A:B,2,0) -> 43 | H7: կին | I7: =VLOOKUP(H7,gender!A:B,2,0) -> #N/A | J7: 448 | K7: 448 | L7: 1 | M7: DEFACTO | N7: =VLOOKUP(M7,brand!A:B,2,0) -> 823 | O7: =UPPER(Q7) -> TURKEY | P7: =VLOOKUP(O7,country!A:B,2,0) -> 1840 | Q7: TURKEY | R7: =PROPER(S7) -> 76% Պոլիեսթեր, 24% Բամբակ | S7: 76% պոլիեսթեր, 24% բամբակ | T7: =VLOOKUP(R7,material!A:B,2,0) -> #N/A | U7: DEFACTO | W7: XL | X7: =VLOOKUP(W7,SIZE!A:B,2,0) -> 124 | Y7: 0 | Z7: բեժ | AA7: =VLOOKUP(Z7,COLOR!A:B,2,0) -> #N/A
A8: 7 | B8: 60000003774 | C8: 61061000000 | D8: ԿԱՆԱՑԻ ԵՎ ԱՂՋԿԱ ԲԼՈՒԶՆԵՐ ԲԱՄԲԱԿԵ ՄԱՆՎԱԾՔԻՑ | E8: =PROPER(F8) -> Բլուզ | F8: բլուզ | G8: =VLOOKUP(E8,subcategory!A:B,2,0) -> 77 | H8: կին | I8: =VLOOKUP(H8,gender!A:B,2,0) -> #N/A | J8: 172 | K8: 172 | L8: 1 | M8: DEFACTO | N8: =VLOOKUP(M8,brand!A:B,2,0) -> 823 | O8: =UPPER(Q8) -> TURKEY | P8: =VLOOKUP(O8,country!A:B,2,0) -> 1840 | Q8: TURKEY | R8: =PROPER(S8) -> 53% Պոլիեսթեր, 27% Վիսկոզա | S8: 53% պոլիեսթեր, 27% վիսկոզա | T8: =VLOOKUP(R8,material!A:B,2,0) -> #N/A | U8: DEFACTO | W8: S | X8: =VLOOKUP(W8,SIZE!A:B,2,0) -> 122 | Y8: 0 | Z8: սև | AA8: =VLOOKUP(Z8,COLOR!A:B,2,0) -> 20
A9: 8 | B9: 60000003786 | C9: 62034319000 | D9: ՏՂԱՄԱՐԴՈՒ ԵՎ ՏՂԱՅԻ ՏԱԲԱՏՆԵՐ ՍԻՆԹԵՏԻԿ ԹԵԼԵՐԻՑ | E9: =PROPER(F9) -> Տաբատներ | F9: տաբատներ | G9: =VLOOKUP(E9,subcategory!A:B,2,0) -> 93 | H9: տղամարդու | I9: =VLOOKUP(H9,gender!A:B,2,0) -> #N/A | J9: 490 | K9: 490 | L9: 1 | M9: DEFACTO | N9: =VLOOKUP(M9,brand!A:B,2,0) -> 823 | O9: =UPPER(Q9) -> TURKEY | P9: =VLOOKUP(O9,country!A:B,2,0) -> 1840 | Q9: TURKEY | R9: =PROPER(S9) -> 55% Պոլիամիդ, 45% Բամբակ | S9: 55% պոլիամիդ, 45% բամբակ | T9: =VLOOKUP(R9,material!A:B,2,0) -> #N/A | U9: DEFACTO | W9: S | X9: =VLOOKUP(W9,SIZE!A:B,2,0) -> 122 | Y9: 0 | Z9: մուգ կապույտ | AA9: =VLOOKUP(Z9,COLOR!A:B,2,0) -> 25
A10: 9 | B10: 60000003754 | C10: 61042300000 | D10: ԿԱՆԱՑԻ ՏՈՊ ԻՐ ԳԼԽԱՐԿՈՎ ՍԻՆԹԵՏԻԿ ԹԵԼԵՐԻՑ | E10: =PROPER(F10) -> Տոպ+Գլխարկ | F10: տոպ+գլխարկ | G10: =VLOOKUP(E10,subcategory!A:B,2,0) -> 481 | H10: կին | I10: =VLOOKUP(H10,gender!A:B,2,0) -> #N/A | J10: 102 | K10: 102 | L10: 1 | M10: DEFACTO | N10: =VLOOKUP(M10,brand!A:B,2,0) -> 823 | O10: =UPPER(Q10) -> TURKEY | P10: =VLOOKUP(O10,country!A:B,2,0) -> 1840 | Q10: TURKEY | R10: =PROPER(S10) -> 100% Պոլիեսթեր | S10: 100% պոլիեսթեր | T10: =VLOOKUP(R10,material!A:B,2,0) -> #N/A | U10: DEFACTO | W10: S | X10: =VLOOKUP(W10,SIZE!A:B,2,0) -> 122 | Y10: 0 | Z10: մուգ կապույտ | AA10: =VLOOKUP(Z10,COLOR!A:B,2,0) -> 25
A11: 10 | B11: 60000003792 | C11: 61103091000 | D11: ՏՂԱՄԱՐԴՈՒ ՍՎԻՏԵՐ-ՎՈԴՈԼԱԶԿԱ ՍԻՆԹԵՏԻԿ ԹԵԼԵՐԻՑ | E11: =PROPER(F11) -> Սվիտեր Վդ․ | F11: սվիտեր վդ․ | G11: =VLOOKUP(E11,subcategory!A:B,2,0) -> #N/A | H11: տղամարդու | I11: =VLOOKUP(H11,gender!A:B,2,0) -> #N/A | J11: 296 | K11: 296 | L11: 1 | M11: DEFACTO | N11: =VLOOKUP(M11,brand!A:B,2,0) -> 823 | O11: =UPPER(Q11) -> TURKEY | P11: =VLOOKUP(O11,country!A:B,2,0) -> 1840 | Q11: TURKEY | R11: =PROPER(S11) -> 100% Ակրիլ | S11: 100% ակրիլ | T11: =VLOOKUP(R11,material!A:B,2,0) -> #N/A | U11: DEFACTO | W11: XL | X11: =VLOOKUP(W11,SIZE!A:B,2,0) -> 124 | Y11: 0 | Z11: բեժ | AA11: =VLOOKUP(Z11,COLOR!A:B,2,0) -> #N/A
A12: 11 | B12: 60000003788 | C12: 62071100000 | D12: ՏՂԱՄԱՐԴՈՒ ՎԱՐՏԻՔՆԵՐ ԲԱՄԲԱԿԵ ՄԱՆՎԱԾՔԻՑ ՀԱՎԱՔԱԾՈՒ 3 ՀԱՏԻՑ | E12: =PROPER(F12) -> Վարտիկ Սեթ 3Հատ | F12: վարտիկ սեթ 3հատ | G12: =VLOOKUP(E12,subcategory!A:B,2,0) -> #N/A | H12: տղամարդու | I12: =VLOOKUP(H12,gender!A:B,2,0) -> #N/A | J12: 224 | K12: 224 | L12: 1 | M12: DEFACTO | N12: =VLOOKUP(M12,brand!A:B,2,0) -> 823 | O12: =UPPER(Q12) -> BANGLADESH | P12: =VLOOKUP(O12,country!A:B,2,0) -> 7485 | Q12: BANGLADESH | R12: =PROPER(S12) -> 100% Բամբակ | S12: 100% բամբակ | T12: =VLOOKUP(R12,material!A:B,2,0) -> #N/A | U12: DEFACTO | W12: XL | X12: =VLOOKUP(W12,SIZE!A:B,2,0) -> 124 | Y12: 0 | Z12: գույնզգույն | AA12: =VLOOKUP(Z12,COLOR!A:B,2,0) -> 17
A13: 12 | B13: 60000003797 | C13: 62024000010 | D13: ԿԱՆԱՑԻ ՎԵՐԱՐԿՈՒ ՔԻՄԻԱԿԱՆ ԹԵԼԵՐԻՑ | E13: =PROPER(F13) -> Վերարկու | F13: վերարկու | G13: =VLOOKUP(E13,subcategory!A:B,2,0) -> 92 | H13: կին | I13: =VLOOKUP(H13,gender!A:B,2,0) -> #N/A | J13: 1534 | K13: 1534 | L13: 1 | M13: DEFACTO | N13: =VLOOKUP(M13,brand!A:B,2,0) -> 823 | O13: =UPPER(Q13) -> MYANMAR | P13: =VLOOKUP(O13,country!A:B,2,0) -> 7495 | Q13: MYANMAR | R13: =PROPER(S13) -> 100% Պոլիեսթեր | S13: 100% պոլիեսթեր | T13: =VLOOKUP(R13,material!A:B,2,0) -> #N/A | U13: DEFACTO | W13: XL | X13: =VLOOKUP(W13,SIZE!A:B,2,0) -> 124 | Y13: 0 | Z13: սև | AA13: =VLOOKUP(Z13,COLOR!A:B,2,0) -> 20
A14: 13 | B14: 40000001659 | C14: 61091000000 | D14: ԿԱՆԱՑԻ ԵՎ ԱՂՋԿԱ ՇԱՊԻԿՆԵՐ ԲԱՄԲԱԿԵ ՄԱՆՎԱԾՔԻՑ | E14: =PROPER(F14) -> Կարճաթև Շապիկ | F14: Կարճաթև շապիկ | G14: =VLOOKUP(E14,subcategory!A:B,2,0) -> 22 | H14: կին | I14: =VLOOKUP(H14,gender!A:B,2,0) -> #N/A | J14: 135 | K14: 135 | L14: 1 | M14: DEFACTO | N14: =VLOOKUP(M14,brand!A:B,2,0) -> 823 | O14: =UPPER(Q14) -> TURKEY | P14: =VLOOKUP(O14,country!A:B,2,0) -> 1840 | Q14: TURKEY | R14: =PROPER(S14) -> 100% Բամբակ | S14: 100% բամբակ | T14: =VLOOKUP(R14,material!A:B,2,0) -> #N/A | U14: DEFACTO | W14: M | X14: =VLOOKUP(W14,SIZE!A:B,2,0) -> 119 | Y14: 0 | Z14: սև | AA14: =VLOOKUP(Z14,COLOR!A:B,2,0) -> 20
A15: 14 | B15: 40000001654 | C15: 62034235000 | D15: ՏՂԱՄԱՐԴՈՒ ՏԱԲԱՏՆԵՐ ԲԱՄԲԱԿԵ ՄԱՆՎԱԾՔԻՑ | E15: =PROPER(F15) -> Տաբատներ | F15: տաբատներ | G15: =VLOOKUP(E15,subcategory!A:B,2,0) -> 93 | H15: տղամարդու | I15: =VLOOKUP(H15,gender!A:B,2,0) -> #N/A | J15: 245 | K15: 245 | L15: 1 | M15: DEFACTO | N15: =VLOOKUP(M15,brand!A:B,2,0) -> 823 | O15: =UPPER(Q15) -> TURKEY | P15: =VLOOKUP(O15,country!A:B,2,0) -> 1840 | Q15: TURKEY | R15: =PROPER(S15) -> 100% Բամբակ | S15: 100% բամբակ | T15: =VLOOKUP(R15,material!A:B,2,0) -> #N/A | U15: DEFACTO | W15: 30 | X15: =VLOOKUP(W15,SIZE!A:B,2,0) -> 22 | Y15: 0 | Z15: կրեմագույն | AA15: =VLOOKUP(Z15,COLOR!A:B,2,0) -> 16
A16: 15 | B16: 40000001636 | C16: 61091000000 | D16: ԿԱՆԱՑԻ ԵՎ ԱՂՋԿԱ ԵՐԿԱՐԱԹԵՎ ՇԱՊԻԿՆԵՐ ԲԱՄԲԱԿԵ ՄԱՆՎԱԾՔԻՑ | E16: =PROPER(F16) -> Երկարաթև Շապիկ | F16: երկարաթև շապիկ | G16: =VLOOKUP(E16,subcategory!A:B,2,0) -> 21 | H16: կին | I16: =VLOOKUP(H16,gender!A:B,2,0) -> #N/A | J16: 130 | K16: 130 | L16: 1 | M16: DEFACTO | N16: =VLOOKUP(M16,brand!A:B,2,0) -> 823 | O16: =UPPER(Q16) -> BANGLADESH | P16: =VLOOKUP(O16,country!A:B,2,0) -> 7485 | Q16: BANGLADESH | R16: =PROPER(S16) -> 95% Բամբակ, 5% Էլաստան | S16: 95% բամբակ, 5% էլաստան | T16: =VLOOKUP(R16,material!A:B,2,0) -> #N/A | U16: DEFACTO | W16: S | X16: =VLOOKUP(W16,SIZE!A:B,2,0) -> 122 | Y16: 0 | Z16: մոխրագույն | AA16: =VLOOKUP(Z16,COLOR!A:B,2,0) -> 8
A17: 16 | B17: 40000001632 | C17: 62046239000 | D17: ԿԱՆԱՑԻ ՏԱԲԱՏՆԵՐ ԲԱՄԲԱԿԵ ՄԱՆՎԱԾՔԻՑ | E17: =PROPER(F17) -> Տաբատներ | F17: տաբատներ | G17: =VLOOKUP(E17,subcategory!A:B,2,0) -> 93 | H17: կին | I17: =VLOOKUP(H17,gender!A:B,2,0) -> #N/A | J17: 255 | K17: 255 | L17: 1 | M17: DEFACTO | N17: =VLOOKUP(M17,brand!A:B,2,0) -> 823 | O17: =UPPER(Q17) -> TURKEY | P17: =VLOOKUP(O17,country!A:B,2,0) -> 1840 | Q17: TURKEY | R17: =PROPER(S17) -> 26% Պոլիեսթեր, 70% Բամբակ | S17: 26% պոլիեսթեր, 70% բամբակ | T17: =VLOOKUP(R17,material!A:B,2,0) -> #N/A | U17: DEFACTO | W17: 36 | X17: =VLOOKUP(W17,SIZE!A:B,2,0) -> 52 | Y17: 0 | Z17: երկանգույն | AA17: =VLOOKUP(Z17,COLOR!A:B,2,0) -> #N/A
A18: 17 | B18: 40000002134 | C18: 61112090000 | D18: ՏՂԱ ԵՐԵԽԱՅԻ ՇԱՊԻԿ ԻՐ ՏԱԲԱՏՈՎ ԲԱՄԲԱԿԵ ՄԱՆՎԱԾՔԻՑ ՄԻՆՉԵՎ 86 ՍՄ ՀԱՍԱԿ ՈՒՆԵՑՈՂ | E18: =PROPER(F18) -> Շապիկ+Տաբատ | F18: շապիկ+տաբատ | G18: =VLOOKUP(E18,subcategory!A:B,2,0) -> #N/A | H18: նորածին տղա | I18: =VLOOKUP(H18,gender!A:B,2,0) -> 7 | J18: 100 | K18: 100 | L18: 1 | M18: CHICCO | N18: =VLOOKUP(M18,brand!A:B,2,0) -> 608 | O18: =UPPER(Q18) -> CHINA | P18: =VLOOKUP(O18,country!A:B,2,0) -> 7497 | Q18: CHINA | R18: =PROPER(S18) -> Բամբակ | S18: բամբակ | T18: =VLOOKUP(R18,material!A:B,2,0) -> 9 | U18: chicco | W18: 1ամիս | X18: =VLOOKUP(W18,SIZE!A:B,2,0) -> #N/A | Y18: 0 | Z18: սպիտակ | AA18: =VLOOKUP(Z18,COLOR!A:B,2,0) -> 12
A19: 18 | B19: 40000002133 | C19: 61112090000 | D19: ԱՂՋԻԿ ԵՐԵԽԱՅԻ ԲԱՃԿՈՆ ԲԱՄԲԱԿԵ ՄԱՆՎԱԾՔԻՑ ՄԻՆՉԵՎ 86 ՍՄ ՀԱՍԱԿ ՈՒՆԵՑՈՂ | E19: =PROPER(F19) -> Բաճկոն | F19: բաճկոն | G19: =VLOOKUP(E19,subcategory!A:B,2,0) -> 14 | H19: նորածին աղջկա | I19: =VLOOKUP(H19,gender!A:B,2,0) -> #N/A | J19: 115 | K19: 115 | L19: 1 | M19: CHICCO | N19: =VLOOKUP(M19,brand!A:B,2,0) -> 608 | O19: =UPPER(Q19) -> INDIA | P19: =VLOOKUP(O19,country!A:B,2,0) -> 7505 | Q19: INDIA | R19: =PROPER(S19) -> Բամբակ | S19: բամբակ | T19: =VLOOKUP(R19,material!A:B,2,0) -> 9 | U19: chicco | W19: 6ամիս | X19: =VLOOKUP(W19,SIZE!A:B,2,0) -> #N/A | Y19: 29.99 | Z19: Վարդագույն | AA19: =VLOOKUP(Z19,COLOR!A:B,2,0) -> 13
A20: 19 | B20: 40000002132 | C20: 61142000000 | D20: ՏՂԱՅԻ ԲՈԴԻՆԵՐ ԲԱՄԲԱԿԵ ՄԱՆՎԱԾՔԻՑ | E20: =PROPER(F20) -> Բոդի | F20: բոդի | G20: =VLOOKUP(E20,subcategory!A:B,2,0) -> 15 | H20: տղա | I20: =VLOOKUP(H20,gender!A:B,2,0) -> #N/A | J20: 235 | K20: 235 | L20: 1 | M20: CHICCO | N20: =VLOOKUP(M20,brand!A:B,2,0) -> 608 | O20: =UPPER(Q20) -> CHINA | P20: =VLOOKUP(O20,country!A:B,2,0) -> 7497 | Q20: CHINA | R20: =PROPER(S20) -> Բամբակ | S20: բամբակ | T20: =VLOOKUP(R20,material!A:B,2,0) -> 9 | U20: chicco | W20: 18ամիս | X20: =VLOOKUP(W20,SIZE!A:B,2,0) -> #N/A | Y20: 29.99 | Z20: կարմիր | AA20: =VLOOKUP(Z20,COLOR!A:B,2,0) -> 1
A21: 20 | B21: 40000002131 | C21: 62034235000 | D21: ՏՂԱՄԱՐԴՈՒ ԵՎ ՏՂԱՅԻ ՏԱԲԱՏՆԵՐ ԲԱՄԲԱԿԵ ՄԱՆՎԱԾՔԻՑ | E21: =PROPER(F21) -> Տաբատներ | F21: տաբատներ | G21: =VLOOKUP(E21,subcategory!A:B,2,0) -> 93 | H21: տղա | I21: =VLOOKUP(H21,gender!A:B,2,0) -> #N/A | J21: 115 | K21: 115 | L21: 1 | M21: CHICCO | N21: =VLOOKUP(M21,brand!A:B,2,0) -> 608 | O21: =UPPER(Q21) -> BANGLADESH | P21: =VLOOKUP(O21,country!A:B,2,0) -> 7485 | Q21: BANGLADESH | R21: =PROPER(S21) -> Բամբակ | S21: բամբակ | T21: =VLOOKUP(R21,material!A:B,2,0) -> 9 | U21: chicco | W21: 18ամիս | X21: =VLOOKUP(W21,SIZE!A:B,2,0) -> #N/A | Y21: 10.99 | Z21: կապույտ | AA21: =VLOOKUP(Z21,COLOR!A:B,2,0) -> 5
A22: 21 | B22: 40000002130 | C22: 61044200000 | D22: ԱՂՋԿԱ ՇՐՋԱԶԳԵՍՏՆԵՐ ԲԱՄԲԱԿԵ ՄԱՆՎԱԾՔԻՑ | E22: =PROPER(F22) -> Զգեստ | F22: զգեստ | G22: =VLOOKUP(E22,subcategory!A:B,2,0) -> 43 | H22: աղջկա | I22: =VLOOKUP(H22,gender!A:B,2,0) -> #N/A | J22: 110 | K22: 110 | L22: 1 | M22: CHICCO | N22: =VLOOKUP(M22,brand!A:B,2,0) -> 608 | O22: =UPPER(Q22) -> INDIA | P22: =VLOOKUP(O22,country!A:B,2,0) -> 7505 | Q22: INDIA | R22: =PROPER(S22) -> Բամբակ | S22: բամբակ | T22: =VLOOKUP(R22,material!A:B,2,0) -> 9 | U22: chicco | W22: 15ամիս | X22: =VLOOKUP(W22,SIZE!A:B,2,0) -> #N/A | Y22: 0 | Z22: սպիտակ | AA22: =VLOOKUP(Z22,COLOR!A:B,2,0) -> 12
A23: 22 | B23: 40000002129 | C23: 61091000000 | D23: ՏՂԱՅԻ ՇԱՊԻԿՆԵՐ ԲԱՄԲԱԿԵ ՄԱՆՎԱԾՔԻՑ | E23: =PROPER(F23) -> Շապիկ | F23: շապիկ | G23: =VLOOKUP(E23,subcategory!A:B,2,0) -> 73 | H23: տղա | I23: =VLOOKUP(H23,gender!A:B,2,0) -> #N/A | J23: 55 | K23: 55 | L23: 1 | M23: CHICCO | N23: =VLOOKUP(M23,brand!A:B,2,0) -> 608 | O23: =UPPER(Q23) -> BANGLADESH | P23: =VLOOKUP(O23,country!A:B,2,0) -> 7485 | Q23: BANGLADESH | R23: =PROPER(S23) -> Բամբակ | S23: բամբակ | T23: =VLOOKUP(R23,material!A:B,2,0) -> 9 | U23: chicco | W23: 18ամիս | X23: =VLOOKUP(W23,SIZE!A:B,2,0) -> #N/A | Y23: 12.99 | Z23: սպիտակ | AA23: =VLOOKUP(Z23,COLOR!A:B,2,0) -> 12
A24: 23 | B24: 40000002128 | C24: 61044200000 | D24: ԱՂՋԿԱ ՇՐՋԱԶԳԵՍՏՆԵՐ ԲԱՄԲԱԿԵ ՄԱՆՎԱԾՔԻՑ | E24: =PROPER(F24) -> Զգեստ | F24: զգեստ | G24: =VLOOKUP(E24,subcategory!A:B,2,0) -> 43 | H24: աղջկա | I24: =VLOOKUP(H24,gender!A:B,2,0) -> #N/A | J24: 140 | K24: 140 | L24: 1 | M24: CHICCO | N24: =VLOOKUP(M24,brand!A:B,2,0) -> 608 | O24: =UPPER(Q24) -> INDIA | P24: =VLOOKUP(O24,country!A:B,2,0) -> 7505 | Q24: INDIA | R24: =PROPER(S24) -> Բամբակ | S24: բամբակ | T24: =VLOOKUP(R24,material!A:B,2,0) -> 9 | U24: chicco | W24: 6տ | X24: =VLOOKUP(W24,SIZE!A:B,2,0) -> #N/A | Y24: 0 | Z24: սպիտակ | AA24: =VLOOKUP(Z24,COLOR!A:B,2,0) -> 12
A25: 24 | B25: 40000002127 | C25: 61112090000 | D25: ԱՂՋԻԿ ԵՐԵԽԱՅԻ ՇՐՋԱԶԳԵՍՏՆԵՐ ԲԱՄԲԱԿԵ ՄԱՆՎԱԾՔԻՑ ՄԻՆՉԵՎ 86 ՍՄ ՀԱՍԱԿ ՈՒՆԵՑՈՂ | E25: =PROPER(F25) -> Զգեստ | F25: զգեստ | G25: =VLOOKUP(E25,subcategory!A:B,2,0) -> 43 | H25: նորածին աղջկա | I25: =VLOOKUP(H25,gender!A:B,2,0) -> #N/A | J25: 95 | K25: 95 | L25: 1 | M25: CHICCO | N25: =VLOOKUP(M25,brand!A:B,2,0) -> 608 | O25: =UPPER(Q25) -> INDIA | P25: =VLOOKUP(O25,country!A:B,2,0) -> 7505 | Q25: INDIA | R25: =PROPER(S25) -> Բամբակ | S25: բամբակ | T25: =VLOOKUP(R25,material!A:B,2,0) -> 9 | U25: chicco | W25: 9ամիս | X25: =VLOOKUP(W25,SIZE!A:B,2,0) -> #N/A | Y25: 0 | Z25: սպիտակ | AA25: =VLOOKUP(Z25,COLOR!A:B,2,0) -> 12
A26: 25 | B26: 40000002126 | C26: 61112090000 | D26: ԱՂՋԻԿ ԵՐԵԽԱՅԻ ՇԱՊԻԿՆԵՐ ԲԱՄԲԱԿԵ ՄԱՆՎԱԾՔԻՑ ՄԻՆՉԵՎ 86 ՍՄ ՀԱՍԱԿ ՈՒՆԵՑՈՂ | E26: =PROPER(F26) -> Շապիկ | F26: շապիկ | G26: =VLOOKUP(E26,subcategory!A:B,2,0) -> 73 | H26: նորածին աղջկա | I26: =VLOOKUP(H26,gender!A:B,2,0) -> #N/A | J26: 59 | K26: 59 | L26: 1 | M26: CHICCO | N26: =VLOOKUP(M26,brand!A:B,2,0) -> 608 | O26: =UPPER(Q26) -> INDIA | P26: =VLOOKUP(O26,country!A:B,2,0) -> 7505 | Q26: INDIA | R26: =PROPER(S26) -> Բամբակ | S26: բամբակ | T26: =VLOOKUP(R26,material!A:B,2,0) -> 9 | U26: chicco | W26: 6ամիս | X26: =VLOOKUP(W26,SIZE!A:B,2,0) -> #N/A | Y26: 22.99 | Z26: սպիտակ | AA26: =VLOOKUP(Z26,COLOR!A:B,2,0) -> 12
A27: 26 | B27: 40000002125 | C27: 61102099000 | D27: ԱՂՋԿԱ ՍՎԻՏՉՐԵՐ ԲԱՄԲԱԿԵ ԱՆՎԱԾՔԻՑ | E27: =PROPER(F27) -> Սվիտեր | F27: սվիտեր | G27: =VLOOKUP(E27,subcategory!A:B,2,0) -> #N/A | H27: աղջկա | I27: =VLOOKUP(H27,gender!A:B,2,0) -> #N/A | J27: 240 | K27: 240 | L27: 1 | M27: CHICCO | N27: =VLOOKUP(M27,brand!A:B,2,0) -> 608 | O27: =UPPER(Q27) -> INDIA | P27: =VLOOKUP(O27,country!A:B,2,0) -> 7505 | Q27: INDIA | R27: =PROPER(S27) -> Բամբակ | S27: բամբակ | T27: =VLOOKUP(R27,material!A:B,2,0) -> 9 | U27: chicco | W27: 9-10տ | X27: =VLOOKUP(W27,SIZE!A:B,2,0) -> #N/A | Y27: 0 | Z27: Վարդագույն | AA27: =VLOOKUP(Z27,COLOR!A:B,2,0) -> 13
A28: 27 | B28: 40000002124 | C28: 62046239000 | D28: ԱՂՋԿԱ ՏԱԲԱՏՆԵՐ ԲԱՄԲԱԿԵ ՄԱՆՎԱԾՔԻՑ | E28: =PROPER(F28) -> Տաբատներ | F28: տաբատներ | G28: =VLOOKUP(E28,subcategory!A:B,2,0) -> 93 | H28: աղջկա | I28: =VLOOKUP(H28,gender!A:B,2,0) -> #N/A | J28: 140 | K28: 140 | L28: 1 | M28: CHICCO | N28: =VLOOKUP(M28,brand!A:B,2,0) -> 608 | O28: =UPPER(Q28) -> INDIA | P28: =VLOOKUP(O28,country!A:B,2,0) -> 7505 | Q28: INDIA | R28: =PROPER(S28) -> Բամբակ | S28: բամբակ | T28: =VLOOKUP(R28,material!A:B,2,0) -> 9 | U28: chicco | W28: 9-10տ | X28: =VLOOKUP(W28,SIZE!A:B,2,0) -> #N/A | Y28: 0 | Z28: կապույտ | AA28: =VLOOKUP(Z28,COLOR!A:B,2,0) -> 5
A29: 28 | B29: 40000002123 | C29: 61044200000 | D29: ԱՂՋԿԱ ՇՐՋԱԶԳԵՍՏՆԵՐ ԲԱՄԲԱԿԵ ՄԱՆՎԱԾՔԻՑ | E29: =PROPER(F29) -> Զգեստ | F29: զգեստ | G29: =VLOOKUP(E29,subcategory!A:B,2,0) -> 43 | H29: աղջկա | I29: =VLOOKUP(H29,gender!A:B,2,0) -> #N/A | J29: 105 | K29: 105 | L29: 1 | M29: CHICCO | N29: =VLOOKUP(M29,brand!A:B,2,0) -> 608 | O29: =UPPER(Q29) -> INDIA | P29: =VLOOKUP(O29,country!A:B,2,0) -> 7505 | Q29: INDIA | R29: =PROPER(S29) -> Բամբակ | S29: բամբակ | T29: =VLOOKUP(R29,material!A:B,2,0) -> 9 | U29: chicco | W29: 2տ | X29: =VLOOKUP(W29,SIZE!A:B,2,0) -> #N/A | Y29: 35.99 | Z29: սպիտակ | AA29: =VLOOKUP(Z29,COLOR!A:B,2,0) -> 12
... A103: 102 | B103: 60000002256 | C103: 62046239000 | D103: ԿԱՆԱՑԻ ԵՎ ԱՂՋԿԱ ՏԱԲԱՏՆԵՐ ԲԱՄԲԱԿԵ ՄԱՆՎԱԾՔԻՑ | E103: =PROPER(F103) -> Տաբատներ | F103: տաբատներ | G103: =VLOOKUP(E103,subcategory!A:B,2,0) -> 93 | H103: աղջկա | I103: =VLOOKUP(H103,gender!A:B,2,0) -> #N/A | J103: 105 | K103: 105 | L103: 1 | M103: CHICCO | N103: =VLOOKUP(M103,brand!A:B,2,0) -> 608 | O103: =UPPER(Q103) -> BANGLADESH | P103: =VLOOKUP(O103,country!A:B,2,0) -> 7485 | Q103: BANGLADESH | R103: =PROPER(S103) -> Բամբակ | S103: Բամբակ | T103: =VLOOKUP(R103,material!A:B,2,0) -> 9 | U103: chicco | W103: 2տ | X103: =VLOOKUP(W103,SIZE!A:B,2,0) -> #N/A | Y103: 0 | Z103: վարդագույն | AA103: =VLOOKUP(Z103,COLOR!A:B,2,0) -> 13
A104: 103 | B104: 60000002255 | C104: 62114210000 | D104: ԱՂՋԿԱ ԳՈԳՆՈՑՆԵՐ ԲԱՄԲԱԿԵ ՄԱՆՎԱԾՔԻՑ | E104: =PROPER(F104) -> Գոգնոց | F104: գոգնոց | G104: =VLOOKUP(E104,subcategory!A:B,2,0) -> 285 | H104: աղջկա | I104: =VLOOKUP(H104,gender!A:B,2,0) -> #N/A | J104: 90 | K104: 90 | L104: 1 | M104: CHICCO | N104: =VLOOKUP(M104,brand!A:B,2,0) -> 608 | O104: =UPPER(Q104) -> CHINA | P104: =VLOOKUP(O104,country!A:B,2,0) -> 7497 | Q104: CHINA | R104: =PROPER(S104) -> Բամբակ | S104: Բամբակ | T104: =VLOOKUP(R104,material!A:B,2,0) -> 9 | U104: chicco | W104: 0 | X104: =VLOOKUP(W104,SIZE!A:B,2,0) -> 4 | Y104: 9.99 | Z104: սպիտակ | AA104: =VLOOKUP(Z104,COLOR!A:B,2,0) -> 12
A105: 104 | B105: 60000002254 | C105: 61046200000 | D105: ԱՂՋԿԱ ՇՈՐՏԵՐ ԲԱՄԲԱԿԵ ՄԱՆՎԱԾՔԻՑ | E105: =PROPER(F105) -> Շորտ | F105: շորտ | G105: =VLOOKUP(E105,subcategory!A:B,2,0) -> 24 | H105: աղջկա | I105: =VLOOKUP(H105,gender!A:B,2,0) -> #N/A | J105: 60 | K105: 60 | L105: 1 | M105: CHICCO | N105: =VLOOKUP(M105,brand!A:B,2,0) -> 608 | O105: =UPPER(Q105) -> BANGLADESH | P105: =VLOOKUP(O105,country!A:B,2,0) -> 7485 | Q105: BANGLADESH | R105: =PROPER(S105) -> Բամբակ | S105: Բամբակ | T105: =VLOOKUP(R105,material!A:B,2,0) -> 9 | U105: chicco | W105: 4տ | X105: =VLOOKUP(W105,SIZE!A:B,2,0) -> #N/A | Y105: 9.99 | Z105: կանաչ | AA105: =VLOOKUP(Z105,COLOR!A:B,2,0) -> 4
A106: 105 | B106: 60000002253 | C106: 61046200000 | D106: ԱՂՋԿԱ ՇՈՐՏԵՐ ԲԱՄԲԱԿԵ ՄԱՆՎԱԾՔԻՑ | E106: =PROPER(F106) -> Շորտ | F106: շորտ | G106: =VLOOKUP(E106,subcategory!A:B,2,0) -> 24 | H106: աղջկա | I106: =VLOOKUP(H106,gender!A:B,2,0) -> #N/A | J106: 40 | K106: 40 | L106: 1 | M106: CHICCO | N106: =VLOOKUP(M106,brand!A:B,2,0) -> 608 | O106: =UPPER(Q106) -> BANGLADESH | P106: =VLOOKUP(O106,country!A:B,2,0) -> 7485 | Q106: BANGLADESH | R106: =PROPER(S106) -> Բամբակ | S106: Բամբակ | T106: =VLOOKUP(R106,material!A:B,2,0) -> 9 | U106: chicco | W106: 18ամիս | X106: =VLOOKUP(W106,SIZE!A:B,2,0) -> #N/A | Y106: 0 | Z106: վարդագույն | AA106: =VLOOKUP(Z106,COLOR!A:B,2,0) -> 13
A107: 106 | B107: 60000002252 | C107: 61159500000 | D107: ՏՂԱՅԻ ԳՈՒԼՊԱՆԵՐ ԲԱՄԲԱԿԵ ՄԱՆՎԱԾՔԻՑ ՀԱՎԱՔԱԾՈՒ 2 ԶՈՒՅԳԻՑ | E107: =PROPER(F107) -> Գուլպա 2Զույգ | F107: գուլպա 2զույգ | G107: =VLOOKUP(E107,subcategory!A:B,2,0) -> #N/A | H107: տղա | I107: =VLOOKUP(H107,gender!A:B,2,0) -> #N/A | J107: 25 | K107: 25 | L107: 1 | M107: CHICCO | N107: =VLOOKUP(M107,brand!A:B,2,0) -> 608 | O107: =UPPER(Q107) -> CHINA | P107: =VLOOKUP(O107,country!A:B,2,0) -> 7497 | Q107: CHINA | R107: =PROPER(S107) -> Բամբակ | S107: Բամբակ | T107: =VLOOKUP(R107,material!A:B,2,0) -> 9 | U107: chicco | W107: 1-3տ | X107: =VLOOKUP(W107,SIZE!A:B,2,0) -> #N/A | Y107: 9.99 | Z107: երկնագույն | AA107: =VLOOKUP(Z107,COLOR!A:B,2,0) -> #N/A
A108: 107 | B108: 60000002251 | C108: 61046200000 | D108: ԱՂՋԿԱ ՇՈՐՏԵՐ ԲԱՄԲԱԿԵ ՄԱՆՎԱԾՔԻՑ | E108: =PROPER(F108) -> Շորտ | F108: շորտ | G108: =VLOOKUP(E108,subcategory!A:B,2,0) -> 24 | H108: աղջկա | I108: =VLOOKUP(H108,gender!A:B,2,0) -> #N/A | J108: 50 | K108: 50 | L108: 1 | M108: CHICCO | N108: =VLOOKUP(M108,brand!A:B,2,0) -> 608 | O108: =UPPER(Q108) -> BANGLADESH | P108: =VLOOKUP(O108,country!A:B,2,0) -> 7485 | Q108: BANGLADESH | R108: =PROPER(S108) -> Բամբակ | S108: բամբակ | T108: =VLOOKUP(R108,material!A:B,2,0) -> 9 | U108: chicco | W108: 5տ | X108: =VLOOKUP(W108,SIZE!A:B,2,0) -> #N/A | Y108: 8.99 | Z108: վարդագույն | AA108: =VLOOKUP(Z108,COLOR!A:B,2,0) -> 13
A109: 108 | B109: 60000002250 | C109: 62024000090 | D109: ԿԱՆԱՑԻ ԵՎ ԱՂՋԿԱ ԲԱՃԿՈՆՆԵՐ ՔԻՄԻԱԿԱՆ ԹԵԼԵՐԻՑ | E109: =PROPER(F109) -> Բաճկոն | F109: բաճկոն | G109: =VLOOKUP(E109,subcategory!A:B,2,0) -> 14 | H109: աղջկա | I109: =VLOOKUP(H109,gender!A:B,2,0) -> #N/A | J109: 115 | K109: 115 | L109: 1 | M109: CHICCO | N109: =VLOOKUP(M109,brand!A:B,2,0) -> 608 | O109: =UPPER(Q109) -> MYANMAR | P109: =VLOOKUP(O109,country!A:B,2,0) -> 7495 | Q109: MYANMAR | R109: =PROPER(S109) -> Պոլիեսթեր | S109: պոլիեսթեր | T109: =VLOOKUP(R109,material!A:B,2,0) -> 37 | U109: chicco | W109: 3տ | X109: =VLOOKUP(W109,SIZE!A:B,2,0) -> #N/A | Y109: 19.99 | Z109: վարդագույն | AA109: =VLOOKUP(Z109,COLOR!A:B,2,0) -> 13
A110: 109 | B110: 60000002249 | C110: 61112090000 | D110: ԱՂՋԻԿ ԵՐԵԽԱՅԻ ՇՐՋԱԶԳԵՍՏՆԵՐ ԲԱՄԲԱԿԵ ՄԱՆՎԱԾՔԻՑ ՄԻՆՉԵՎ 86 ՍՄ ՀԱՍԱԿ ՈՒՆԵՑՈՂ | E110: =PROPER(F110) -> Զգեստ | F110: զգեստ | G110: =VLOOKUP(E110,subcategory!A:B,2,0) -> 43 | H110: նորածին աղջկա | I110: =VLOOKUP(H110,gender!A:B,2,0) -> #N/A | J110: 135 | K110: 135 | L110: 1 | M110: CHICCO | N110: =VLOOKUP(M110,brand!A:B,2,0) -> 608 | O110: =UPPER(Q110) -> INDIA | P110: =VLOOKUP(O110,country!A:B,2,0) -> 7505 | Q110: INDIA | R110: =PROPER(S110) -> Բամբակ | S110: բամբակ | T110: =VLOOKUP(R110,material!A:B,2,0) -> 9 | U110: chicco | W110: 9ամիս | X110: =VLOOKUP(W110,SIZE!A:B,2,0) -> #N/A | Y110: 27.99 | Z110: սև | AA110: =VLOOKUP(Z110,COLOR!A:B,2,0) -> 20
A111: 110 | B111: 60000002248 | C111: 61112090000 | D111: ՏՂԱ ԵՐԵԽԱՅԻ ԲՈԴԻՆԵՐ ԲԱՄԲԱԿԵ ՄԱՆՎԱԾՔԻՑ ՄԻՆՉԵՎ 86 ՍՄ ՀԱՍԱԿ ՈՒՆԵՑՈՂ | E111: =PROPER(F111) -> Բոդի | F111: բոդի | G111: =VLOOKUP(E111,subcategory!A:B,2,0) -> 15 | H111: նորածին տղա | I111: =VLOOKUP(H111,gender!A:B,2,0) -> 7 | J111: 65 | K111: 65 | L111: 1 | M111: CHICCO | N111: =VLOOKUP(M111,brand!A:B,2,0) -> 608 | O111: =UPPER(Q111) -> TURKEY | P111: =VLOOKUP(O111,country!A:B,2,0) -> 1840 | Q111: TURKEY | R111: =PROPER(S111) -> Բամբակ | S111: բամբակ | T111: =VLOOKUP(R111,material!A:B,2,0) -> 9 | U111: chicco | W111: 1ամիս | X111: =VLOOKUP(W111,SIZE!A:B,2,0) -> #N/A | Y111: 20.99 | Z111: դեղին | AA111: =VLOOKUP(Z111,COLOR!A:B,2,0) -> 3
A112: 111 | B112: 60000002247 | C112: 62034235000 | D112: ՏՂԱՅԻ ՏԱԲԱՏՆԵՐ ԲԱՄԲԱԿԵ ՄԱՆՎԱԾՔԻՑ | E112: =PROPER(F112) -> Տաբատներ | F112: տաբատներ | G112: =VLOOKUP(E112,subcategory!A:B,2,0) -> 93 | H112: տղա | I112: =VLOOKUP(H112,gender!A:B,2,0) -> #N/A | J112: 180 | K112: 180 | L112: 1 | M112: CHICCO | N112: =VLOOKUP(M112,brand!A:B,2,0) -> 608 | O112: =UPPER(Q112) -> INDIA | P112: =VLOOKUP(O112,country!A:B,2,0) -> 7505 | Q112: INDIA | R112: =PROPER(S112) -> Բամբակ | S112: բամբակ | T112: =VLOOKUP(R112,material!A:B,2,0) -> 9 | U112: chicco | W112: 4տ | X112: =VLOOKUP(W112,SIZE!A:B,2,0) -> #N/A | Y112: 25.99 | Z112: կապույտ | AA112: =VLOOKUP(Z112,COLOR!A:B,2,0) -> 5
A113: 112 | B113: 60000002246 | C113: 61113090000 | D113: ՏՂԱ ԵՐԵԽԱՅԻ ՇՈՐՏԵՐ ՍԻՆԹԵՏԻԿ ԹԵԼԵՐԻՑ ՄԻՆՉԵՎ 86 ՍՄ ՀԱՍԱԿ ՈՒՆԵՑՈՂ | E113: =PROPER(F113) -> Շորտ | F113: շորտ | G113: =VLOOKUP(E113,subcategory!A:B,2,0) -> 24 | H113: տղա | I113: =VLOOKUP(H113,gender!A:B,2,0) -> #N/A | J113: 70 | K113: 70 | L113: 1 | M113: CHICCO | N113: =VLOOKUP(M113,brand!A:B,2,0) -> 608 | O113: =UPPER(Q113) -> CHINA | P113: =VLOOKUP(O113,country!A:B,2,0) -> 7497 | Q113: CHINA | R113: =PROPER(S113) -> Պոլիեսթեր | S113: պոլիեսթեր | T113: =VLOOKUP(R113,material!A:B,2,0) -> 37 | U113: chicco | W113: 1տ | X113: =VLOOKUP(W113,SIZE!A:B,2,0) -> #N/A | Y113: 20.99 | Z113: կապույտ | AA113: =VLOOKUP(Z113,COLOR!A:B,2,0) -> 5
...

Sheet ALL Exp-Asos
A1: N | B1: Code | C1: HS code | D1: name | E1: Sub-category | F1: Sub-category id | G1: Gender | H1: Gender id | I1: Netto | J1: pc | K1: Brutto | L1: Brand | M1: Brand id | N1: Country | O1: Country id | P1: Material | Q1: Material id | R1: Package | S1: Package Id | T1: Size | U1: Size id | V1: Original price | W1: Color | X1: Color id
A2: 1 | B2: 40000001111 | C2: 61102091000 | D2: ՏՂԱՄԱՐԴՈՒ ՀՈՒԴԻՆԵՐ ԲԱՄԲԱԿԵ ՄԱՆՎԱԾՔԻՑ | E2: Հուդի | F2: 18 | G2: Տղամարդկանց | H2: 1 | I2: 0.055 | J2: 1 | K2: 0.055 | L2: PETROL | M2: 881 | N2: BANGLADESH | O2: 7485 | P2: Բամբակ/Պոլիեսթեր | Q2: 9-37 | R2: Mix Brand | S2: 1000320 | T2: S | U2: 122 | V2: 0 | W2: Կապույտ | X2: 5
A3: 2 | B3: 40000001112 | C3: 61103091000 | D3: ՏՂԱՄԱՐԴՈՒ ՍՎԻՏՐԵՐ ՔԻՄԻԱԿԱՆ ԹԵԼԵՐԻՑ | E3: Սվիտրեր | F3: 88 | G3: Տղամարդկանց | H3: 1 | I3: 0.334 | J3: 1 | K3: 0.334 | L3: PETROL | M3: 881 | N3: BANGLADESH | O3: 7485 | P3: Բամբակ/Ակրիլ | Q3: 9-2 | R3: Mix Brand | S3: 1000320 | T3: S | U3: 122 | V3: 0 | W3: Կապույտ | X3: 5
A4: 3 | B4: 40000001113 | C4: 64041990000 | D4: ՏՂԱՄԱՐԴՈՒ ԿՈՇԻԿ ՏԵՔՏՍԻԼԵ ԵՐԵՍԱՄԱՍՈՎ ՌԵՏԻՆԵ ԿՈՇԿԱՏԱԿՈՎ | E4: Կոշիկ | F4: 55 | G4: Տղամարդկանց | H4: 1 | I4: 1.086 | J4: 1 | K4: 1.086 | L4: REGATTA | M4: 254 | N4: CHINA | O4: 7497 | P4: Տակացու Ռետին, Վրան Կտոր | Q4: 102-25 | R4: Mix Brand | S4: 1000320 | T4: 43 | U4: 289 | V4: 0 | W4: Կապույտ | X4: 5
A5: 4 | B5: 40000001114 | C5: 64041990000 | D5: ԿԱՆԱՑԻ ԿՈՇԻԿՆԵՐ ՏԵՔՏՍԻԼԵ ԵՐԵՍԱՄԱՍՈՎ ՌԵՏԻՆԵ ԿՈՇԿԱՏԱԿՈՎ | E5: Կոշիկ | F5: 55 | G5: Կանանց | H5: 2 | I5: 0.042 | J5: 1 | K5: 0.042 | L5: UNKNOWN | M5: 880 | N5: CHINA | O5: 7497 | P5: Տակացու Ռետին, Վրան Կտոր | Q5: 102-25 | R5: Mix Brand | S5: 1000320 | T5: 38 | U5: 64 | V5: 0 | W5: Սպիտակ | X5: 12
A6: 5 | B6: 40000001110 | C6: 62034235000 | D6: ՏՂԱՅԻ ՏԱԲԱՏՆԵՐ ԲԱՄԲԱԿԵ ՄԱՆՎԱԾՔԻՑ | E6: Տաբատներ | F6: 93 | G6: Տղաների | H6: 4 | I6: 0.304 | J6: 1 | K6: 0.304 | L6: S. OLIVER | M6: 17 | N6: BANGLADESH | O6: 7485 | P6: Բամբակ | Q6: 9 | R6: Mix Brand | S6: 1000320 | T6: US 12-13 | U6: 633 | V6: EUR 40 | W6: Կանաչ | X6: 4
A7: 6 | B7: 40000001109 | C7: 64039998000 | D7: ԿԱՆԱՑԻ ԿՈՇԻԿ ԲՆԱԿԱՆ ԿԱՇՎԵ ԵՐԵՍԱՄԱՍՈՎ , ՊՈԼԻՄԵՐԱՅԻՆ ԿՈՇԿԱՏԱԿՈՎ | E7: Կոշիկ | F7: 55 | G7: Կանանց | H7: 2 | I7: 0.85 | J7: 1 | K7: 1.418 | L7: RAGE AGE | M7: 882 | N7: POLAND | O7: 1805 | P7: Տակացու Պոլիմեր, Վրան Զամշ | Q7: 101-79 | R7: Mix Brand | S7: 1000320 | T7: 39 | U7: 275 | V7: 0 | W7: Կարմիր | X7: 1
A8: 7 | B8: 40000001108 | C8: 64041910000 | D8: ՏՂԱՄԱՐԴՈՒ ՀՈՂԱԹԱՓ ՏԵՔՍՏԻԼԵ ԵՐԵՍԱՄԱՍՈՎ , ՊՈԼԻՄԵՐԱՅԻՆ ԿՈՇԿԱՏՈՎ | E8: Հողաթափ | F8: 310 | G8: Unisex | H8: 5 | I8: 0.388 | J8: 1 | K8: 0.582 | L8: UGG | M8: 296 | N8: VIETNAM | O8: 7579 | P8: Բուրդ/Լիոսել | Q8: 11-54 | R8: Mix Brand | S8: 1000320 | T8: 41 | U8: 288 | V8: 0 | W8: Շագանակագույն | X8: 10
A9: 8 | B9: 40000001107 | C9: 62024000010 | D9: ԿԱՆԱՑԻ ՎԵՐԱՐԿՈՒՆԵՐ ՔԻՄԻԱԿԱՆ ԹԵԼԵՐԻՑ | E9: Վերարկու | F9: 92 | G9: Կանանց | H9: 2 | I9: 1.102 | J9: 1 | K9: 1.102 | L9: TOM TAILOR | M9: 5 | N9: VIETNAM | O9: 7579 | P9: Պոլիեսթեր | Q9: 37 | R9: Mix Brand | S9: 1000320 | T9: L | U9: 3 | V9: EUR 100 | W9: Վարդագույն | X9: 13
A10: 9 | B10: 40000001106 | C10: 61102091000 | D10: ՏՂԱՄԱՐԴՈՒ ԵՎ ՏՂԱՅԻ ՍՎԻՏՐԵՐ ԲԱՄԲԱԿԵ ՄԱՆՎԱԾՔԻՑ | E10: Սվիտրեր | F10: 88 | G10: Տղամարդկանց | H10: 1 | I10: 0.344 | J10: 1 | K10: 0.344 | L10: PETROL | M10: 881 | N10: BANGLADESH | O10: 7485 | P10: Բամբակ/Ակրիլ | Q10: 9-2 | R10: Mix Brand | S10: 1000320 | T10: M | U10: 119 | V10: EUR 60 | W10: Կանաչ | X10: 4
A11: 10 | B11: 40000001105 | C11: 62014000000 | D11: ՏՂԱՄԱՐԴՈՒ ՎԵՐԱՐԿՈՒՆԵՐ ՔԻՄԻԱԿԱՆ ԹԵԼԵՐԻՑ | E11: Վերարկու | F11: 92 | G11: Տղամարդկանց | H11: 1 | I11: 1.136 | J11: 1 | K11: 1.136 | L11: PETROL | M11: 881 | N11: CHINA | O11: 7497 | P11: Պոլիեսթեր | Q11: 37 | R11: Mix Brand | S11: 1000320 | T11: XL | U11: 124 | V11: EUR 120 | W11: Սև | X11: 20
A12: 11 | B12: 40000001104 | C12: 62014000000 | D12: ՏՂԱՄԱՐԴՈՒ ՎԵՐԱՐԿՈՒՆԵՐ ՔԻՄԻԱԿԱՆ ԹԵԼԵՐԻՑ | E12: Վերարկու | F12: 92 | G12: Տղամարդկանց | H12: 1 | I12: 1.194 | J12: 1 | K12: 1.194 | L12: PETROL | M12: 881 | N12: CHINA | O12: 7497 | P12: Պոլիեսթեր | Q12: 37 | R12: Mix Brand | S12: 1000320 | T12: L | U12: 3 | V12: EUR 120 | W12: Սև | X12: 20
A13: 12 | B13: 40000001103 | C13: 62014000000 | D13: ՏՂԱՄԱՐԴՈՒ ՎԵՐԱՐԿՈՒՆԵՐ ՔԻՄԻԱԿԱՆ ԹԵԼԵՐԻՑ | E13: Վերարկու | F13: 92 | G13: Տղամարդկանց | H13: 1 | I13: 1.076 | J13: 1 | K13: 1.076 | L13: PETROL | M13: 881 | N13: CHINA | O13: 7497 | P13: Պոլիեսթեր | Q13: 37 | R13: Mix Brand | S13: 1000320 | T13: L | U13: 3 | V13: EUR 120 | W13: Կապույտ | X13: 5
A14: 13 | B14: 40000001102 | C14: 62014000000 | D14: ՏՂԱՄԱՐԴՈՒ ՎԵՐԱՐԿՈՒՆԵՐ ՔԻՄԻԱԿԱՆ ԹԵԼԵՐԻՑ | E14: Վերարկու | F14: 92 | G14: Տղամարդկանց | H14: 1 | I14: 1.038 | J14: 1 | K14: 1.038 | L14: PETROL | M14: 881 | N14: CHINA | O14: 7497 | P14: Պոլիեսթեր | Q14: 37 | R14: Mix Brand | S14: 1000320 | T14: M | U14: 119 | V14: EUR 120 | W14: Սև | X14: 20
A15: 14 | B15: 40000001101 | C15: 62024000010 | D15: ԿԱՆԱՑԻ ՎԵՐԱՐԿՈՒՆԵՐ ՔԻՄԻԱԿԱՆ ԹԵԼԵՐԻՑ | E15: Վերարկու | F15: 92 | G15: Կանանց | H15: 2 | I15: 1.06 | J15: 1 | K15: 1.06 | L15: TOM TAILOR | M15: 5 | N15: VIETNAM | O15: 7579 | P15: Պոլիեսթեր | Q15: 37 | R15: Mix Brand | S15: 1000320 | T15: L | U15: 3 | V15: EUR 100 | W15: Վարդագույն | X15: 13
A16: 15 | B16: 40000001100 | C16: 61102091000 | D16: ՏՂԱՄԱՐԴՈՒ ՀՈՒԴԻՆԵՐ ԲԱՄԲԱԿԵ ՄԱՆՎԱԾՔԻՑ | E16: Հուդի | F16: 18 | G16: Տղամարդկանց | H16: 1 | I16: 0.926 | J16: 1 | K16: 0.926 | L16: CARHARTT | M16: 791 | N16: PAKISTAN | O16: 7550 | P16: Բամբակ/Պոլիեսթեր | Q16: 9-37 | R16: Mix Brand | S16: 1000320 | T16: XL | U16: 124 | V16: 0 | W16: Կանաչ | X16: 4
A17: 16 | B17: 40000001099 | C17: 61102091000 | D17: ՏՂԱՄԱՐԴՈՒ ՀՈՒԴԻՆԵՐ ԲԱՄԲԱԿԵ ՄԱՆՎԱԾՔԻՑ | E17: Հուդի | F17: 18 | G17: Տղամարդկանց | H17: 1 | I17: 0.854 | J17: 1 | K17: 0.854 | L17: CARHARTT | M17: 791 | N17: PAKISTAN | O17: 7550 | P17: Բամբակ/Պոլիեսթեր | Q17: 9-37 | R17: Mix Brand | S17: 1000320 | T17: M | U17: 119 | V17: 0 | W17: Կանաչ | X17: 4
A18: 17 | B18: 40000001098 | C18: 61102091000 | D18: ՏՂԱՄԱՐԴՈՒ ԵՎ ՏՂԱՅԻ ՍՎԻՏՐԵՐ ԲԱՄԲԱԿԵ ՄԱՆՎԱԾՔԻՑ | E18: Սվիտրեր | F18: 88 | G18: Տղամարդկանց | H18: 1 | I18: 0.402 | J18: 1 | K18: 0.402 | L18: PETROL | M18: 881 | N18: BANGLADESH | O18: 7485 | P18: Բամբակ/Ակրիլ | Q18: 9-2 | R18: Mix Brand | S18: 1000320 | T18: XL | U18: 124 | V18: EUR 60 | W18: Կապույտ | X18: 5
A19: 18 | B19: 40000001097 | C19: 62013000000 | D19: ՏՂԱՄԱՐԴՈՒ ՎԵՐԱՐԿՈՒՆԵՐ ԲԱՄԲԱԿԵ ՄԱՆՎԱԾՔԻՑ | E19: Վերարկու | F19: 92 | G19: Տղամարդկանց | H19: 1 | I19: 0.556 | J19: 1 | K19: 0.556 | L19: PETROL | M19: 881 | N19: CHINA | O19: 7497 | P19: Բամբակ/Պոլիեսթեր | Q19: 9-37 | R19: Mix Brand | S19: 1000320 | T19: M | U19: 119 | V19: EUR 90 | W19: Սև | X19: 20
A20: 19 | B20: 40000001096 | C20: 62013000000 | D20: ՏՂԱՄԱՐԴՈՒ ՎԵՐԱՐԿՈՒ ԲԱՄԲԱԿԵ ՄԱՆՎԱԾՔԻՑ | E20: Վերարկու | F20: 92 | G20: Տղամարդկանց | H20: 1 | I20: 0.466 | J20: 1 | K20: 0.466 | L20: PETROL | M20: 881 | N20: BANGLADESH | O20: 7485 | P20: Բամբակ/Ակրիլ | Q20: 9-2 | R20: Mix Brand | S20: 1000320 | T20: XL | U20: 124 | V20: EUR 70 | W20: Սև | X20: 20
A21: 20 | B21: 40000001095 | C21: 64039991000 | D21: ՏՂԱՅԻ ԿՈՇԻԿ ԲՆԱԿԱՆ ԶԱՄՇԵ ԵՐԵՍԱՄԱՍՈՎ , ՊՈԼԻՄԵՐԱՅԻՆ ԿՈՇԿԱՏԱԿՈՎ ՄԻՆՉԵՎ 24ՍՄ ՆԵՐԲԱՆԻ ԵՐԿԱՐՈՒԹՅԱՄԲ | E21: Կոշիկ | F21: 55 | G21: Տղաների | H21: 4 | I21: 0.348 | J21: 1 | K21: 0.526 | L21: GEOX | M21: 883 | N21: ITALY | O21: 1760 | P21: Տակացու Պոլիմեր, Վրան Զամշ | Q21: 101-79 | R21: Mix Brand | S21: 1000320 | T21: 31 | U21: 140 | V21: EUR 31 | W21: Կապույտ | X21: 5
A22: 21 | B22: 40000001094 | C22: 64029991000 | D22: ԱՂՋԿԱ ԲՈԿՈՏԻԿ ԱՐՀԵՍՏԱԿԱՆ ԿԱՇՎԵ ԵՐԵՍԱՄԱՍՈՎ , ՌԵՏԻՆԵ ԿՈՇԿԱՏԱԿՈՎ ՄԻՆՉԵՎ 24ՍՄ ՆԵՐԲԱՆԻ ԵՐԿԱՐՈՒԹՅԱՄԲ | E22: Սանդալ | F22: 66 | G22: Աղջիկների | H22: 3 | I22: 0.326 | J22: 1 | K22: 0.48 | L22: CHICCO | M22: 608 | N22: CHINA | O22: 7497 | P22: Պոլիուրեթան | Q22: 104 | R22: Mix Brand | S22: 1000320 | T22: 31 | U22: 140 | V22: 0 | W22: Սպիտակ | X22: 12
A23: 22 | B23: 40000001093 | C23: 61091000000 | D23: ՏՂԱՄԱՐԴՈՒ ԵՎ ՏՂԱՅԻ ՇԱՊԻԿՆԵՐ ԲԱՄԲԱԿԵ ՄԱՆՎԱԾՔԻՑ | E23: Շապիկ | F23: 73 | G23: Տղամարդկանց | H23: 1 | I23: 0.162 | J23: 1 | K23: 0.162 | L23: PETROL | M23: 881 | N23: BANGLADESH | O23: 7485 | P23: Բամբակ | Q23: 9 | R23: Mix Brand | S23: 1000320 | T23: XL | U23: 124 | V23: EUR 20 | W23: Կապույտ | X23: 5
A24: 23 | B24: 40000001092 | C24: 61102091000 | D24: ՏՂԱՄԱՐԴՈՒ ՀՈՒԴԻՆԵՐ ԲԱՄԲԱԿԵ ՄԱՆՎԱԾՔԻՑ | E24: Հուդի | F24: 18 | G24: Տղամարդկանց | H24: 1 | I24: 0.576 | J24: 1 | K24: 0.576 | L24: PETROL | M24: 881 | N24: BANGLADESH | O24: 7485 | P24: Բամբակ | Q24: 9 | R24: Mix Brand | S24: 1000320 | T24: M | U24: 119 | V24: EUR 46 | W24: Կապույտ | X24: 5
A25: 24 | B25: 40000001091 | C25: 61051000000 | D25: ՏՂԱՄԱՐԴՈՒ ՎԵՐՆԱՇԱՊԻԿՆԵՐ ԲԱՄԲԱԿԵ ՄԱՆՎԱԾՔԻՑ | E25: Վերնաշապիկ | F25: 82 | G25: Տղամարդկանց | H25: 1 | I25: 0.236 | J25: 1 | K25: 0.236 | L25: PETROL | M25: 881 | N25: BANGLADESH | O25: 7485 | P25: Բամբակ | Q25: 9 | R25: Mix Brand | S25: 1000320 | T25: L | U25: 3 | V25: EUR 60 | W25: Գույնզգույն | X25: 17
A26: 25 | B26: 40000001090 | C26: 61051000000 | D26: ՏՂԱՄԱՐԴՈՒ ԵՎ ՏՂԱՅԻ ՎԵՐՆԱՇԱՊԻԿՆԵՐ ԲԱՄԲԱԿԵ ՄԱՆՎԱԾՔԻՑ | E26: Վերնաշապիկ | F26: 82 | G26: Տղամարդկանց | H26: 1 | I26: 0.466 | J26: 1 | K26: 0.466 | L26: PETROL | M26: 881 | N26: INDIA | O26: 7505 | P26: Բամբակ | Q26: 9 | R26: Mix Brand | S26: 1000320 | T26: M | U26: 119 | V26: EUR 80 | W26: Գույնզգույն | X26: 17
A27: 26 | B27: 40000001089 | C27: 62013000000 | D27: ՏՂԱՄԱՐԴՈՒ ՎԵՐԱՐԿՈՒՆԵՐ ԲԱՄԲԱԿԵ ՄԱՆՎԱԾՔԻՑ | E27: Վերարկու | F27: 92 | G27: Տղամարդկանց | H27: 1 | I27: 0.516 | J27: 1 | K27: 0.516 | L27: PETROL | M27: 881 | N27: CHINA | O27: 7497 | P27: Բամբակ | Q27: 9 | R27: Mix Brand | S27: 1000320 | T27: S | U27: 122 | V27: EUR 90 | W27: Կաթնագույն | X27: 23
A28: 27 | B28: 40000001088 | C28: 61102091000 | D28: ՏՂԱՄԱՐԴՈՒ ՀՈՒԴԻՆԵՐ ԲԱՄԲԱԿԵ ՄԱՆՎԱԾՔԻՑ | E28: Հուդի | F28: 18 | G28: Տղամարդկանց | H28: 1 | I28: 0.62 | J28: 1 | K28: 0.62 | L28: PETROL | M28: 881 | N28: BANGLADESH | O28: 7485 | P28: Բամբակ/Ակրիլ | Q28: 9-2 | R28: Mix Brand | S28: 1000320 | T28: M | U28: 119 | V28: EUR 90 | W28: Կաթնագույն | X28: 23
A29: 28 | B29: 40000001087 | C29: 61091000000 | D29: ՏՂԱՄԱՐԴՈՒ ԵՎ ՏՂԱՅԻ ՇԱՊԻԿՆԵՐ ԲԱՄԲԱԿԵ ՄԱՆՎԱԾՔԻՑ | E29: Շապիկ | F29: 73 | G29: Տղամարդկանց | H29: 1 | I29: 0.202 | J29: 1 | K29: 0.202 | L29: PETROL | M29: 881 | N29: BANGLADESH | O29: 7485 | P29: Բամբակ | Q29: 9 | R29: Mix Brand | S29: 1000320 | T29: XL | U29: 124 | V29: EUR 28 | W29: Կաթնագույն | X29: 23
A30: 29 | B30: 40000001086 | C30: 61102091000 | D30: ՏՂԱՄԱՐԴՈՒ ԵՎ ՏՂԱՅԻ ՍՎԻՏՐԵՐ ԲԱՄԲԱԿԵ ՄԱՆՎԱԾՔԻՑ | E30: Սվիտրեր | F30: 88 | G30: Տղամարդկանց | H30: 1 | I30: 0.474 | J30: 1 | K30: 0.474 | L30: PETROL | M30: 881 | N30: BANGLADESH | O30: 7485 | P30: Բամբակ | Q30: 9 | R30: Mix Brand | S30: 1000320 | T30: L | U30: 3 | V30: EUR 50 | W30: Կաթնագույն | X30: 23
A31: 30 | B31: 40000001085 | C31: 61102091000 | D31: ՏՂԱՄԱՐԴՈՒ ՀՈՒԴԻՆԵՐ ԲԱՄԲԱԿԵ ՄԱՆՎԱԾՔԻՑ | E31: Հուդի | F31: 18 | G31: Տղամարդկանց | H31: 1 | I31: 0.634 | J31: 1 | K31: 0.634 | L31: PETROL | M31: 881 | N31: BANGLADESH | O31: 7485 | P31: Բամբակ | Q31: 9 | R31: Mix Brand | S31: 1000320 | T31: L | U31: 3 | V31: EUR 60 | W31: Կապույտ | X31: 5
A32: 31 | B32: 40000001084 | C32: 61102091000 | D32: ՏՂԱՄԱՐԴՈՒ ԵՎ ՏՂԱՅԻ ՍՎԻՏՐԵՐ ԲԱՄԲԱԿԵ ՄԱՆՎԱԾՔԻՑ | E32: Սվիտրեր | F32: 88 | G32: Տղամարդկանց | H32: 1 | I32: 0.494 | J32: 1 | K32: 0.494 | L32: PETROL | M32: 881 | N32: BANGLADESH | O32: 7485 | P32: Բամբակ | Q32: 9 | R32: Mix Brand | S32: 1000320 | T32: S | U32: 122 | V32: EUR 50 | W32: Կապույտ | X32: 5
A33: 32 | B33: 40000001083 | C33: 61045300000 | D33: ԿԱՆԱՑԻ ԵՎ ԱՂՋԿԱ ԿԻՍԱՇՐՋԱԶԳԵՍՏՆԵՐ ՍԻՆԹԵՏԻԿ ԹԵԼԵՐԻՑ | E33: Կիսաշրջազգեստ | F33: 53 | G33: Կանանց | H33: 2 | I33: 0.226 | J33: 1 | K33: 0.226 | L33: ONLY | M33: 28 | N33: CHINA | O33: 7497 | P33: Պոլիեսթեր | Q33: 37 | R33: Mix Brand | S33: 1000320 | T33: S | U33: 122 | V33: EUR 35 | W33: Սև | X33: 20
A34: 33 | B34: 40000001082 | C34: 62013000000 | D34: ՏՂԱՄԱՐԴՈՒ ՎԵՐԱՐԿՈՒ ԲԱՄԲԱԿԵ ՄԱՆՎԱԾՔԻՑ | E34: Վերարկու | F34: 92 | G34: Տղամարդկանց | H34: 1 | I34: 1.268 | J34: 1 | K34: 1.268 | L34: PETROL | M34: 881 | N34: PAKISTAN | O34: 7550 | P34: Բամբակ/Պոլիեսթեր | Q34: 9-37 | R34: Mix Brand | S34: 1000320 | T34: XL | U34: 124 | V34: EUR 100 | W34: Կանաչ | X34: 4
A35: 34 | B35: 40000001081 | C35: 62034235000 | D35: ՏՂԱՅԻ ՏԱԲԱՏՆԵՐ ԲԱՄԲԱԿԵ ՄԱՆՎԱԾՔԻՑ | E35: Տաբատներ | F35: 93 | G35: Տղաների | H35: 4 | I35: 0.424 | J35: 1 | K35: 0.424 | L35: TIMBERLAND | M35: 457 | N35: BANGLADESH | O35: 7485 | P35: Բամբակ | Q35: 9 | R35: Mix Brand | S35: 1000320 | T35: 36 | U35: 52 | V35: 0 | W35: Սև | X35: 20
A36: 35 | B36: 40000001080 | C36: 64039991000 | D36: ՏՂԱՅԻ ԲՈԿՈՏԻԿ ԲՆԱԿԱՆ ԿԱՇՎԵ ԵՐԵՍԱՄԱՍՈՎ , ՊՈԼԻՄԵՐԱՅԻՆ ԿՈՇԿԱՏԱԿՈՎ ՄԻՆՉԵՎ 24ՍՄ ՆԵՐԲԱՆԻ ԵՐԿԱՐՈՒԹՅԱՄԲ | E36: Սանդալ | F36: 66 | G36: Տղաների | H36: 4 | I36: 0.092 | J36: 1 | K36: 0.092 | L36: CHICCO | M36: 608 | N36: ITALY | O36: 1760 | P36: Տակացու Պոլիմեր, Վրան Կաշի | Q36: 101-20 | R36: Mix Brand | S36: 1000320 | T36: 18 | U36: 2 | V36: 0 | W36: Կապույտ | X36: 5
A37: 36 | B37: 40000001079 | C37: 64029991000 | D37: ԱՂՋԿԱ ԲՈԿՈՏԻԿՆԵՐ ԱՐՀԵՍՏԱԿԱՆ ԿԱՇՎԵ ԵՐԵՍԱՄԱՍՈՎ , ՌԵՏԻՆԵ ԿՈՇԿԱՏԱԿՈՎ ՄԻՆՉԵՎ 24ՍՄ ՆԵՐԲԱՆԻ ԵՐԿԱՐՈՒԹՅԱՄԲ | E37: Սանդալ | F37: 66 | G37: Կանանց | H37: 2 | I37: 0.104 | J37: 1 | K37: 0.104 | L37: CHICCO | M37: 608 | N37: ITALY | O37: 1760 | P37: Պոլիեսթեր | Q37: 37 | R37: Mix Brand | S37: 1000320 | T37: 19 | U37: 370 | V37: EUR 17 (ZEXCHOV 11) | W37: Վարդագույն | X37: 13
A38: 37 | B38: 40000001078 | C38: 64052099000 | D38: ՏՂԱՅԻ ԲՈԿՈՏԻԿՆԵՐ ՏԵՔՍՏԻԼԵ | E38: Սանդալ | F38: 66 | G38: Տղաների | H38: 4 | I38: 0.1 | J38: 1 | K38: 0.1 | L38: CHICCO | M38: 608 | N38: ITALY | O38: 1760 | P38: Բամբակ | Q38: 9 | R38: Mix Brand | S38: 1000320 | T38: 19 | U38: 370 | V38: EUR 15 | W38: Կապույտ | X38: 5
A39: 38 | B39: 40000001077 | C39: 64052099000 | D39: ՏՂԱՅԻ ԲՈԿՈՏԻԿՆԵՐ ՏԵՔՍՏԻԼԵ | E39: Սանդալ | F39: 66 | G39: Տղաների | H39: 4 | I39: 0.096 | J39: 1 | K39: 0.096 | L39: CHICCO | M39: 608 | N39: ITALY | O39: 1760 | P39: Բամբակ | Q39: 9 | R39: Mix Brand | S39: 1000320 | T39: 18 | U39: 2 | V39: EUR 15 | W39: Կապույտ | X39: 5
A40: 39 | B40: 40000001076 | C40: 64029991000 | D40: ԱՂՋԿԱ ԲՈԿՈՏԻԿՆԵՐ ԱՐՀԵՍՏԱԿԱՆ ԿԱՇՎԵ ԵՐԵՍԱՄԱՍՈՎ , ՌԵՏԻՆԵ ԿՈՇԿԱՏԱԿՈՎ ՄԻՆՉԵՎ 24ՍՄ ՆԵՐԲԱՆԻ ԵՐԿԱՐՈՒԹՅԱՄԲ | E40: Սանդալ | F40: 66 | G40: Կանանց | H40: 2 | I40: 0.088 | J40: 1 | K40: 0.088 | L40: CHICCO | M40: 608 | N40: ITALY | O40: 1760 | P40: Պոլիեսթեր | Q40: 37 | R40: Mix Brand | S40: 1000320 | T40: 18 | U40: 2 | V40: EUR 20 | W40: Արծաթագույն | X40: 22
...

Sheet Other
A1: N | B1: Code | C1: HS code | D1: name | E1: Sub-category | F1: Sub-category id | G1: Gender | H1: Gender id | I1: Netto | J1: pc | K1: Brutto | L1: Brand | M1: Brand id | N1: Country | O1: Country id | P1: Material | Q1: Material id | R1: Package | S1: Package Id | T1: Size | U1: Size id | V1: Original price | W1: Color | X1: Color id
A2: 1 | B2: 40000001111 | C2: 61102091000 | D2: ՏՂԱՄԱՐԴՈՒ ՀՈՒԴԻՆԵՐ ԲԱՄԲԱԿԵ ՄԱՆՎԱԾՔԻՑ | E2: Հուդի | F2: 18 | G2: Տղամարդկանց | H2: 1 | I2: 0.055 | J2: 1 | K2: 0.055 | L2: PETROL | M2: 881 | N2: BANGLADESH | O2: 7485 | P2: Բամբակ/Պոլիեսթեր | Q2: 9-37 | R2: Mix Brand | S2: 1000320 | T2: S | U2: 122 | V2: 0 | W2: Կապույտ | X2: 5
A3: 2 | B3: 40000001112 | C3: 61103091000 | D3: ՏՂԱՄԱՐԴՈՒ ՍՎԻՏՐԵՐ ՔԻՄԻԱԿԱՆ ԹԵԼԵՐԻՑ | E3: Սվիտրեր | F3: 88 | G3: Տղամարդկանց | H3: 1 | I3: 0.334 | J3: 1 | K3: 0.334 | L3: PETROL | M3: 881 | N3: BANGLADESH | O3: 7485 | P3: Բամբակ/Ակրիլ | Q3: 9-2 | R3: Mix Brand | S3: 1000320 | T3: S | U3: 122 | V3: 0 | W3: Կապույտ | X3: 5
A4: 3 | B4: 40000001113 | C4: 64041990000 | D4: ՏՂԱՄԱՐԴՈՒ ԿՈՇԻԿ ՏԵՔՏՍԻԼԵ ԵՐԵՍԱՄԱՍՈՎ ՌԵՏԻՆԵ ԿՈՇԿԱՏԱԿՈՎ | E4: Կոշիկ | F4: 55 | G4: Տղամարդկանց | H4: 1 | I4: 1.086 | J4: 1 | K4: 1.086 | L4: REGATTA | M4: 254 | N4: CHINA | O4: 7497 | P4: Տակացու Ռետին, Վրան Կտոր | Q4: 102-25 | R4: Mix Brand | S4: 1000320 | T4: 43 | U4: 289 | V4: 0 | W4: Կապույտ | X4: 5
A5: 4 | B5: 40000001114 | C5: 64041990000 | D5: ԿԱՆԱՑԻ ԿՈՇԻԿՆԵՐ ՏԵՔՏՍԻԼԵ ԵՐԵՍԱՄԱՍՈՎ ՌԵՏԻՆԵ ԿՈՇԿԱՏԱԿՈՎ | E5: Կոշիկ | F5: 55 | G5: Կանանց | H5: 2 | I5: 0.042 | J5: 1 | K5: 0.042 | L5: UNKNOWN | M5: 880 | N5: CHINA | O5: 7497 | P5: Տակացու Ռետին, Վրան Կտոր | Q5: 102-25 | R5: Mix Brand | S5: 1000320 | T5: 38 | U5: 64 | V5: 0 | W5: Սպիտակ | X5: 12
A6: 5 | B6: 40000001110 | C6: 62034235000 | D6: ՏՂԱՅԻ ՏԱԲԱՏՆԵՐ ԲԱՄԲԱԿԵ ՄԱՆՎԱԾՔԻՑ | E6: Տաբատներ | F6: 93 | G6: Տղաների | H6: 4 | I6: 0.304 | J6: 1 | K6: 0.304 | L6: S. OLIVER | M6: 17 | N6: BANGLADESH | O6: 7485 | P6: Բամբակ | Q6: 9 | R6: Mix Brand | S6: 1000320 | T6: US 12-13 | U6: 633 | V6: EUR 40 | W6: Կանաչ | X6: 4
A7: 6 | B7: 40000001109 | C7: 64039998000 | D7: ԿԱՆԱՑԻ ԿՈՇԻԿ ԲՆԱԿԱՆ ԿԱՇՎԵ ԵՐԵՍԱՄԱՍՈՎ , ՊՈԼԻՄԵՐԱՅԻՆ ԿՈՇԿԱՏԱԿՈՎ | E7: Կոշիկ | F7: 55 | G7: Կանանց | H7: 2 | I7: 0.85 | J7: 1 | K7: 1.418 | L7: RAGE AGE | M7: 882 | N7: POLAND | O7: 1805 | P7: Տակացու Պոլիմեր, Վրան Զամշ | Q7: 101-79 | R7: Mix Brand | S7: 1000320 | T7: 39 | U7: 275 | V7: 0 | W7: Կարմիր | X7: 1
A8: 7 | B8: 40000001108 | C8: 64041910000 | D8: ՏՂԱՄԱՐԴՈՒ ՀՈՂԱԹԱՓ ՏԵՔՍՏԻԼԵ ԵՐԵՍԱՄԱՍՈՎ , ՊՈԼԻՄԵՐԱՅԻՆ ԿՈՇԿԱՏՈՎ | E8: Հողաթափ | F8: 310 | G8: Unisex | H8: 5 | I8: 0.388 | J8: 1 | K8: 0.582 | L8: UGG | M8: 296 | N8: VIETNAM | O8: 7579 | P8: Բուրդ/Լիոսել | Q8: 11-54 | R8: Mix Brand | S8: 1000320 | T8: 41 | U8: 288 | V8: 0 | W8: Շագանակագույն | X8: 10
A9: 8 | B9: 40000001107 | C9: 62024000010 | D9: ԿԱՆԱՑԻ ՎԵՐԱՐԿՈՒՆԵՐ ՔԻՄԻԱԿԱՆ ԹԵԼԵՐԻՑ | E9: Վերարկու | F9: 92 | G9: Կանանց | H9: 2 | I9: 1.102 | J9: 1 | K9: 1.102 | L9: TOM TAILOR | M9: 5 | N9: VIETNAM | O9: 7579 | P9: Պոլիեսթեր | Q9: 37 | R9: Mix Brand | S9: 1000320 | T9: L | U9: 3 | V9: EUR 100 | W9: Վարդագույն | X9: 13
